Workbook
Name FromArray_1: _xlfn.ANCHORARRAY(#REF!)
Name FromArray_1: _xlfn.ANCHORARRAY(#REF!)

Sheet RANKING 2025
B2: CIRCUITO NCT VÔLEI DE PRAIA - 2025
B3: Sub 17 Masculino
B4: RANKING
B5: Rk | C5: Atleta | D5: Nome Completo | E5: Centro de Treinamento | F5: UF | G5: 1ª Etapa | H5: 2ª ETAPA | I5: 3ª ETAPA | J5: Total
G6: Arena Caffe | H6: Parque da Cidade | I6: Vamo Beach
B7: 1 | C7: DANI TAVARES 👑 | D7: Daniel Tavares | E7: NCT Võlei de Praia | F7: DF | G7: 200 | H7: 200 | I7: 200 | J7: =SUM(G7:I7) -> 600
C8: DAVI DUTRA 👑 | D8: José Davi Lopes Dutra | F8: DF | G8: 200 | H8: 200 | I8: 200 | J8: =SUM(G8:I8) -> 600
B9: 2 | C9: VICTOR PUTTINI | D9: Victor Puttini de Almeida | E9: JR Integração | F9: DF | G9: 180 | H9: 120 | I9: 160 | J9: =SUM(G9:I9) -> 460
B10: 3 | C10: MARCELLO | D10: Paulo Marcello Aragão Leite | E10: SESC | F10: DF | G10: 140 | H10: 140 | I10: 180 | J10: =SUM(G10:I10) -> 460
B11: 4 | C11: JOÃO VITOR | D11: João Vitor Lopes de Araujo | E11: SESC | F11: DF | G11: 120 | H11: 120 | I11: 120 | J11: =SUM(G11:I11) -> 360
B12: 5 | C12: FELIPE COSTA | D12: Felipe Costa Barros | F12: DF | G12: 0 | H12: 160 | I12: 180 | J12: =SUM(G12:I12) -> 340
B13: 6 | C13: MATEUS LIRA | D13: Mateus Lira da Silva | E13: SESC | F13: DF | G13: 120 | H13: 100 | I13: 120 | J13: =SUM(G13:I13) -> 340
B14: 7 | C14: CAETANO | D14: Caetano Rondon | F14: DF | G14: 100 | H14: 100 | I14: 120 | J14: =SUM(G14:I14) -> 320
C15: EMMANUEL | D15: Emmanuel Carvalho | F15: DF | G15: 100 | H15: 100 | I15: 120 | J15: =SUM(G15:I15) -> 320
C16: SHOYO | D16: Kauã Rodrigues Ventura | E16: NCT Võlei de Praia | F16: DF | G16: 100 | H16: 100 | I16: 120 | J16: =SUM(G16:I16) -> 320
B17: 8 | C17: WYTALO | D17: Wytalo Carvalho de Sousa | F17: GO | G17: 120 | H17: 180 | I17: 0 | J17: =SUM(G17:I17) -> 300
B18: 9 | C18: JURANDIR JR | D18: Jurandir Neres Júnior | E18: JR Integração | F18: DF | G18: 180 | H18: 100 | I18: 0 | J18: =SUM(G18:I18) -> 280
C19: THIAGO FELIPE | D19: Thiago Felipe Araújo Gomes | E19: Cid Gama | F19: GO | G19: 0 | H19: 180 | I19: 100 | J19: =SUM(G19:I19) -> 280
B20: 10 | C20: ARTHUR BRABO | D20: Arthur Pinheiro | E20: JR Integração | F20: DF | G20: 0 | H20: 120 | I20: 160 | J20: =SUM(G20:I20) -> 280
B21: 11 | C21: JOÃO GUILHERME | D21: João Guilherme Araújo de Oliveira | E21: CT BLOQ | F21: DF | G21: 0 | H21: 120 | I21: 140 | J21: =SUM(G21:I21) -> 260
B22: 12 | C22: CAIO MARLEY | D22: Caio Marley de Andrade Ferreira | F22: DF | G22: 0 | H22: 140 | I22: 100 | J22: =SUM(G22:I22) -> 240
C23: WALTER | D23: Walter Luiz Ramos Júnior | E23: JR Integração | F23: DF | G23: 0 | H23: 100 | I23: 140 | J23: =SUM(G23:I23) -> 240
B24: 13 | C24: DAVID AGUIAR | D24: David Miguel Aguiar Silva | E24: SESC | F24: DF | G24: 0 | H24: 120 | I24: 120 | J24: =SUM(G24:I24) -> 240
B25: 14 | C25: CARLOS VICTOR | D25: Carlos Victor Alves de Araújo | F25: DF | G25: 0 | H25: 100 | I25: 120 | J25: =SUM(G25:I25) -> 220
C26: DAVID MAX | D26: David Maxwell Gomes de Souza | F26: DF | G26: 0 | H26: 120 | I26: 100 | J26: =SUM(G26:I26) -> 220
C27: GUI GERREIRO | D27: Guilherme Gerreiro | E27: NCT Võlei de Praia | F27: DF | G27: 120 | H27: 100 | I27: 0 | J27: =SUM(G27:I27) -> 220
C28: HENRICK | D28: Henrick Farias Andrade | F28: DF | G28: 0 | H28: 100 | I28: 120 | J28: =SUM(G28:I28) -> 220
C29: VAVO GUERREIRO | D29: Gustavo Guerreiro | E29: NCT Võlei de Praia | F29: DF | G29: 120 | H29: 100 | I29: 0 | J29: =SUM(G29:I29) -> 220
B30: 15 | C30: PEDRO ALMEIDA | D30: Pedro de Almeida Pires de Campos | F30: DF | G30: 0 | H30: 100 | I30: 100 | J30: =SUM(G30:I30) -> 200
B31: 16 | C31: ANDRÉ | D31: André Luiz de Santana Medrado da Silva | F31: DF | G31: 160 | H31: 0 | I31: 0 | J31: =SUM(G31:I31) -> 160
C32: FERNANDO | D32: Fernando Tavares Nunes da Silva | F32: DF | G32: 160 | H32: 0 | I32: 0 | J32: =SUM(G32:I32) -> 160
C33: RAPAHEL BESSA | D33: Raphael Ribeiro Faitarone Bessa | F33: DF | G33: 0 | H33: 160 | I33: 0 | J33: =SUM(G33:I33) -> 160
B34: 17 | C34: AUGUSTO | D34: Augusto Pires | E34: SESC | F34: DF | G34: 140 | H34: 0 | I34: 0 | J34: =SUM(G34:I34) -> 140
B35: 18 | C35: GREGÓRIO | D35: José Gregório ferreira dos Santos | F35: DF | G35: 120 | H35: 0 | I35: 0 | J35: =SUM(G35:I35) -> 120
C36: MATEUS KOTH | D36: Matheus Koth | F36: DF | G36: 0 | H36: 120 | I36: 0 | J36: =SUM(G36:I36) -> 120
C37: NATHAN | D37: Nathan Henrique da Silva Dias | F37: GO | G37: 120 | H37: 0 | I37: 0 | J37: =SUM(G37:I37) -> 120
C38: RYAN | D38: Ryan Gabriel Dias | F38: DF | G38: 120 | H38: 0 | I38: 0 | J38: =SUM(G38:I38) -> 120
C39: VICTOR HUGO | D39: Victor Hugo Swiderski Rabelo | F39: DF | G39: 0 | H39: 120 | I39: 0 | J39: =SUM(G39:I39) -> 120
B40: 19 | C40: BETO | D40: Roberto César Alves Ferreira | F40: DF | G40: 100 | H40: 0 | I40: 0 | J40: =SUM(G40:I40) -> 100
C41: DAVI MIRANDA | D41: Davi de Miranda Corrêa | E41: Marista | F41: DF | G41: 0 | H41: 100 | I41: 0 | J41: =SUM(G41:I41) -> 100
...

Sheet REGULAMENTO S17M
B2: CIRCUITO NCT VÔLEI DE PRAIA - 2025
B4: REGULAMENTO
B6: 4ª Etapa | D6: SUB 17 Masculino | H6: 1º/08/2025
B7: Arena 61 | H7: sexta-feira
B9: item | C9: Título | D9: Descrição | H9: Observação
B10: 1 | C10: Ranking de entrada | D10: Ranking da temporada 2025. Nos casos de empate, prevalecerá a equipe que tiver a maior quantidade de melhores posições. P. ex.: o empate em pontos entre duplas será resolvido a favor da dupla que tem o maior número de 1º lugares, 2º, etc, e assim sucessivamente. Permancendo o empate, haverá sorteio.
B11: 2 | C11: Distribuição dos grupos | D11: Modelo de serpentina seguindo ranking 2025.
B12: 3 | C12: Quantidade de duplas | D12: 12 duplas (24 atletas).
B13: 4 | C13: Quantidade de jogos | D13: 26 partidas.
B14: 5 | C14: Quantidade de sets* | D14: 1 Set de 21 pontos. | H14: *Exceto a final 2.
B15: 6 | C15: Sistema de disputa da 1ª fase | D15: Todos contra todos no grupo. | H15: 3 jogos por equipe.
B16: 7 | C16: Critérios de desempate para definição de posições no grupo | D16: 1º - nº de vitórias.
D17: 2º - ponto average.
D18: 3º - confronto direto.
D19: 4º - sorteio.
B20: 8 | C20: Classificação no grupo | D20: Classificam-se os dois primeiros colocados de cada grupo e os dois melhores terceiros colocados nos três grupos.
C21: Classificação para quartas-de-final | D21: Classificação geral de 1º a 8º lugares, INDEPENDENTE DA POSIÇÃO DE CLASSIFICAÇÃO NO GRUPO, observando os critérios do item 7.
B22: 9 | C22: Distribuição de confrontos nas quartas-de-final | D22: Cruzamentos: (A: 1º X 8º) versus (B: 4º X 5º) / (C: 2º X 7º) versus (D: 3º X 6º).
B23: 10 | C23: Semifinais | D23: Cruzamentos: (A X B) e (C X D).
B24: 11 | C24: Final 1 (disputa pelo 3º lugar) | D24: Jogo entre os perdedores das semifinais: 1 Set de 21 pontos.
B25: 12 | C25: Final 2: (disputa pelo 1º lugar) | D25: Jogo entre os vencedores das semifinais: 2 sets de 21 pontos e set desempate de 15 pontos.
B26: 13 | C26: Pontuação em Wx0 | D26: As partidas resolvidas pela não apresentação de uma dupla resultará na vitória da dupla que se apresentou, contudo, não haverá saldo de pontos para nenhuma das duplas envolvidas. No caso de duplo W x 0, as duas duplas serão consideradas derrotadas e, consequentemente, sem saldo de pontos.
B27: 14 | C27: Pontuação em partida abandonada por desistência | D27: As partidas em que uma dupla desistir de continuar a partida, terá o placar de 21 (ou diferença de 2 pontos) para a equipe que não desistiu. A dupla que desistiu permanece com a pontuação do momento da desistência.
B28: 15 | C28: Pontuação no Ranking | D28: A distribuição de pontos por atleta ao final de cada etapa se dará da seguinte forma:
D29: 1º lugar: 200 / 2º lugar: 180 / 3º lugar: 160 / 4º lugar: 140 / 5º lugar: 120 / 9º lugar: 100.
B30: 16 | C30: Penalidades | D30: A atleta que agir com desrespeito e violência em relação à arbitragem, adversários, parceiro e qualquer pessoa presente, poderá ser suspenso ou banido do Circuito NCT por deliberação da Comissão Organizadora.
B31: 17 | C31: Suspensão de partidas | D31: As partidas que precisarem ser suspensas por motivos de mau tempo, falta de iluminação e assemelhados, retornará com o placar da interrupção, caso isso ocorra em até 4 horas. Após isso, a partida recomeçará com o placar de 0x0.
B32: 18 | C32: Uniformização | D32: Camiseta oficial do Circuito NCT Vôlei de Praia 2025. | H32: Obrigatória.
D33: Bermudas da mesma cor. | H33: Preferencialmente.
B34: 19 | C34: Horário de início | D34: 13h30, em 3 (três) quadras.
B35: 20 | C35: Local da competição | D35: Arena 61 - localiação enviada no grupo de Whatsapp

Sheet GRUPOS
B2: CIRCUITO NCT VÔLEI DE PRAIA - 2025
B3: 4ª ETAPA - ARENA 61
B4: SUB 17 MASCULINO
B5: 1º de agosto de 2025 - sexta-feira
B6: GRUPOS
B7: Distribuição pelo ranking no modo serpentina
B9: GRUPO A | F9: GRUPO B | J9: GRUPO C
B10: RK | C10: DUPLA | D10: CÓD | F10: RK | G10: DUPLA | H10: CÓD | J10: RK | K10: DUPLA | L10: CÓD
B11: 1º | C11: =C18 -> VICTOR PUTTINI/JURANDIR JR | D11: A1 | F11: 2º | G11: =C19 -> FELIPE COSTA/RAPHAEL BESSA | H11: B1 | J11: 3º | K11: =C20 -> MATEUS LIRA/AUGUSTO | L11: C1
B12: 6º | C12: =C23 -> JOÃO GUILHERME/FELIPE BAPTISTA | D12: A2 | F12: 5º | G12: =C22 -> THIAGO FELIPE/MURILO ALVES | H12: B2 | J12: 4º | K12: =C21 -> CAIO MARLEY/VAVO GUERREIRO | L12: C2
B13: 7º | C13: =C24 -> GUI GERREIRO/THEO PEREIRA | D13: A3 | F13: 8º | G13: =C25 -> LUCAS MENDES/FELIPE ROSSI | H13: B3 | J13: 9º | K13: =C26 -> ENZO ALEXANDRE/ARTHUR AURÉLIO | L13: C3
B14: 12º | C14: =C29 -> ANDRI/JOAQUIM | D14: A4 | F14: 11º | G14: =C28 -> VINÍCIUS ALMEIDA/GUI RODRIGUES | H14: B4 | J14: 10º | K14: =C27 -> LEONARDO/MARCUS VINÍCIUS | L14: C4
B16: RANKING 2025 | O16: RANKING DE ENTRADA (DUPLAS) - MASTER 45+
B17: RK | C17: Dupla | I17: PONTUAÇÃO | L17: CÓD | O17: INSCRIÇÕES | Q17: AT 1 | R17: AT 2 | S17: TOTAL
B18: 1º | C18: VICTOR PUTTINI/JURANDIR JR | I18: 460 + 280 = 740 | L18: A1 | O18: 1º | P18: VICTOR PUTTINI/JURANDIR JR | Q18: 460 | R18: 280 | S18: =SUM(Q18:R18) -> 740
B19: 2º | C19: FELIPE COSTA/RAPHAEL BESSA | I19: 340 + 160 = 500 | L19: B1 | O19: 2º | P19: FELIPE COSTA/RAPHAEL BESSA | Q19: 340 | R19: 160 | S19: =SUM(Q19:R19) -> 500
B20: 3º | C20: MATEUS LIRA/AUGUSTO | I20: 340 + 140 = 480 | L20: C1 | O20: 3º | P20: MATEUS LIRA/AUGUSTO | Q20: 340 | R20: 140 | S20: =SUM(Q20:R20) -> 480
B21: 4º | C21: CAIO MARLEY/VAVO GUERREIRO | I21: 240 + 220 = 460 | L21: C2 | O21: 4º | P21: CAIO MARLEY/VAVO GUERREIRO | Q21: 240 | R21: 220 | S21: =SUM(Q21:R21) -> 460
B22: 5º | C22: THIAGO FELIPE/MURILO ALVES | I22: 280+ 0 = 280 | L22: B2 | O22: 5º | P22: THIAGO FELIPE/MURILO ALVES | Q22: 280 | R22: 0 | S22: =SUM(Q22:R22) -> 280
B23: 6º | C23: JOÃO GUILHERME/FELIPE BAPTISTA | I23: 260 + 0 = 260 | L23: A2 | O23: 6º | P23: JOÃO GUILHERME/FELIPE BAPTISTA | Q23: 260 | R23: 0 | S23: =SUM(Q23:R23) -> 260
B24: 7º | C24: GUI GERREIRO/THEO PEREIRA | I24: 220 = 0 = 220 | L24: A3 | O24: 7º | P24: GUI GERREIRO/THEO PEREIRA | Q24: 220 | R24: 0 | S24: =SUM(Q24:R24) -> 220
B25: 8º | C25: LUCAS MENDES/FELIPE ROSSI | I25: 100 + 0 = 100 | L25: B3 | O25: 8º | P25: LUCAS MENDES/FELIPE ROSSI | Q25: 100 | R25: 0 | S25: =SUM(Q25:R25) -> 100
B26: 9º | C26: ENZO ALEXANDRE/ARTHUR AURÉLIO | I26: 0 | L26: C3 | O26: 9º | P26: ANDRI/JOAQUIM | Q26: 0 | R26: 0 | S26: =SUM(Q26:R26) -> 0
B27: 10º | C27: LEONARDO/MARCUS VINÍCIUS | I27: 0 | L27: C4 | O27: 10º | P27: ENZO ALEXANDRE/ARTHUR AURÉLIO | Q27: 0 | R27: 0 | S27: =SUM(Q27:R27) -> 0
B28: 11º | C28: VINÍCIUS ALMEIDA/GUI RODRIGUES | I28: 0 | L28: B4 | O28: 11º | P28: LEONARDO/MARCUS VINÍCIUS | Q28: 0 | R28: 0 | S28: =SUM(Q28:R28) -> 0
B29: 12º | C29: ANDRI/JOAQUIM | I29: 0 | L29: A4 | O29: 12º | P29: VINÍCIUS ALMEIDA/GUI RODRIGUES | Q29: 0 | R29: 0 | S29: =SUM(Q29:R29) -> 0

Sheet TABELA MASC
B2: CIRCUITO NCT VÔLEI DE PRAIA - 2025
B3: 4ª ETAPA - ARENA 61
B4: SUB 17 MASCULINO
B5: 1º de agosto de 2025 - sexta-feira
B6: TABELA
B8: Fase de grupos
B9: Jogo | C9: Grupo | D9: Hora | E9: Quadra | F9: Código | G9: Equipe 1 | K9: Equipe 2 | L9: Código
B10: 1 | C10: A | F10: A1 | G10: =GRUPOS!C11 -> VICTOR PUTTINI/JURANDIR JR | H10: 21 | I10: X | J10: 10 | K10: =GRUPOS!C14 -> ANDRI/JOAQUIM | L10: A4
B11: 2 | C11: B | F11: B1 | G11: =GRUPOS!G11 -> FELIPE COSTA/RAPHAEL BESSA | H11: 21 | I11: X | J11: 15 | K11: =GRUPOS!G14 -> VINÍCIUS ALMEIDA/GUI RODRIGUES | L11: B4
B12: 3 | C12: C | F12: C1 | G12: =GRUPOS!K11 -> MATEUS LIRA/AUGUSTO | H12: 14 | I12: X | J12: 21 | K12: =GRUPOS!K14 -> LEONARDO/MARCUS VINÍCIUS | L12: C4
B13: 4 | C13: A | F13: A2 | G13: =GRUPOS!C12 -> JOÃO GUILHERME/FELIPE BAPTISTA | H13: 21 | I13: X | J13: 9 | K13: =GRUPOS!C13 -> GUI GERREIRO/THEO PEREIRA | L13: A3
B14: 5 | C14: B | F14: B2 | G14: =GRUPOS!G12 -> THIAGO FELIPE/MURILO ALVES | H14: 15 | I14: X | J14: 21 | K14: =GRUPOS!G13 -> LUCAS MENDES/FELIPE ROSSI | L14: B3
B15: 6 | C15: C | F15: C2 | G15: =GRUPOS!K12 -> CAIO MARLEY/VAVO GUERREIRO | H15: 8 | I15: X | J15: 21 | K15: =GRUPOS!K13 -> ENZO ALEXANDRE/ARTHUR AURÉLIO | L15: C3
B16: 7 | C16: A | F16: A1 | G16: =GRUPOS!C11 -> VICTOR PUTTINI/JURANDIR JR | H16: 21 | I16: X | J16: 19 | K16: =GRUPOS!C13 -> GUI GERREIRO/THEO PEREIRA | L16: A3
B17: 8 | C17: B | F17: B1 | G17: =GRUPOS!G11 -> FELIPE COSTA/RAPHAEL BESSA | H17: 18 | I17: X | J17: 21 | K17: =GRUPOS!G13 -> LUCAS MENDES/FELIPE ROSSI | L17: B3
B18: 9 | C18: C | F18: C1 | G18: =GRUPOS!K11 -> MATEUS LIRA/AUGUSTO | H18: 21 | I18: X | J18: 18 | K18: =GRUPOS!K13 -> ENZO ALEXANDRE/ARTHUR AURÉLIO | L18: C3
B19: 10 | C19: A | F19: A2 | G19: =GRUPOS!C12 -> JOÃO GUILHERME/FELIPE BAPTISTA | H19: 21 | I19: X | J19: 17 | K19: =GRUPOS!C14 -> ANDRI/JOAQUIM | L19: A4
B20: 11 | C20: B | F20: B2 | G20: =GRUPOS!G12 -> THIAGO FELIPE/MURILO ALVES | H20: 12 | I20: X | J20: 21 | K20: =GRUPOS!G14 -> VINÍCIUS ALMEIDA/GUI RODRIGUES | L20: B4
B21: 12 | C21: C | D21: : | F21: C2 | G21: =GRUPOS!K12 -> CAIO MARLEY/VAVO GUERREIRO | H21: 21 | I21: X | J21: 15 | K21: =GRUPOS!K14 -> LEONARDO/MARCUS VINÍCIUS | L21: C4
B22: 13 | C22: A | F22: A1 | G22: =GRUPOS!C11 -> VICTOR PUTTINI/JURANDIR JR | H22: 21 | I22: X | J22: 15 | K22: =GRUPOS!C12 -> JOÃO GUILHERME/FELIPE BAPTISTA | L22: A2
B23: 14 | C23: B | F23: B1 | G23: =GRUPOS!G11 -> FELIPE COSTA/RAPHAEL BESSA | H23: 12 | I23: X | J23: 21 | K23: =GRUPOS!G12 -> THIAGO FELIPE/MURILO ALVES | L23: B2
B24: 15 | C24: C | F24: C1 | G24: =GRUPOS!K11 -> MATEUS LIRA/AUGUSTO | H24: 18 | I24: X | J24: 21 | K24: =GRUPOS!K12 -> CAIO MARLEY/VAVO GUERREIRO | L24: C2
B25: 16 | C25: A | F25: A3 | G25: =GRUPOS!C13 -> GUI GERREIRO/THEO PEREIRA | H25: 18 | I25: X | J25: 21 | K25: =GRUPOS!C14 -> ANDRI/JOAQUIM | L25: A4
B26: 17 | C26: B | F26: B3 | G26: =GRUPOS!G13 -> LUCAS MENDES/FELIPE ROSSI | H26: 12 | I26: X | J26: 21 | K26: =GRUPOS!G14 -> VINÍCIUS ALMEIDA/GUI RODRIGUES | L26: B4
B27: 18 | C27: C | F27: C3 | G27: =GRUPOS!K13 -> ENZO ALEXANDRE/ARTHUR AURÉLIO | H27: 18 | I27: X | J27: 21 | K27: =GRUPOS!K14 -> LEONARDO/MARCUS VINÍCIUS | L27: C4
B30: 19 | C30: QF | F30: 1º | G30: ='AVERAGE MASC'!C45 -> 0 | I30: X | K30: ='AVERAGE MASC'!C52 -> 0 | L30: 8º
B31: 20 | C31: QF | F31: 4º | G31: ='AVERAGE MASC'!C48 -> 0 | I31: X | K31: ='AVERAGE MASC'!C49 -> 0 | L31: 5º
B32: 21 | C32: QF | F32: 2º | G32: ='AVERAGE MASC'!C46 -> 0 | I32: X | K32: ='AVERAGE MASC'!C51 -> 0 | L32: 7º
B33: 22 | C33: QF | F33: 3º | G33: ='AVERAGE MASC'!C47 -> 0 | I33: X | K33: ='AVERAGE MASC'!C50 -> 0 | L33: 6º
B35: Semifinais
B36: 23 | C36: SF | F36: V J 19 | G36: Venc J 19 | I36: X | K36: Venc J 20 | L36: V J 20
B37: 24 | C37: SF | F37: V J 21 | I37: X | L37: V J 22
B39: Final 1: disputa pelo 3º lugar
B40: 25 | C40: F1 | F40: P J 23 | I40: X | L40: P J 24
B42: Final 2: disputa pelo 1º lugar
B43: 26 | C43: F2 | F43: V J 23 | I43: X | L43: V J 24

Sheet AVERAGE MASC
B2: CIRCUITO NCT VÔLEI DE PRAIA - 2025
B3: 4ª ETAPA - ARENA 61
B4: SUB 17 MASCULINO
B5: 1º de agosto de 2025 - sexta-feira
B6: AVERAGE
B10: GRUPO A
B12: =GRUPOS!C11 -> VICTOR PUTTINI/JURANDIR JR | C12: PRO | D12: CONTRA | F12: =GRUPOS!C12 -> JOÃO GUILHERME/FELIPE BAPTISTA | G12: PRO | H12: CONTRA | J12: =GRUPOS!C13 -> GUI GERREIRO/THEO PEREIRA | K12: PRO | L12: CONTRA | N12: =GRUPOS!C14 -> ANDRI/JOAQUIM | O12: PRO | P12: CONTRA
B13: 1 | C13: ='TABELA MASC'!H10 -> 21 | D13: ='TABELA MASC'!J10 -> 10 | F13: 1 | G13: ='TABELA MASC'!H13 -> 21 | H13: ='TABELA MASC'!J13 -> 9 | J13: 1 | K13: ='TABELA MASC'!J13 -> 9 | L13: ='TABELA MASC'!H13 -> 21 | N13: 1 | O13: ='TABELA MASC'!J10 -> 10 | P13: ='TABELA MASC'!H10 -> 21
B14: 2 | C14: ='TABELA MASC'!H16 -> 21 | D14: ='TABELA MASC'!J16 -> 19 | F14: 2 | G14: ='TABELA MASC'!H19 -> 21 | H14: ='TABELA MASC'!J19 -> 17 | J14: 2 | K14: ='TABELA MASC'!J16 -> 19 | L14: ='TABELA MASC'!H16 -> 21 | N14: 2 | O14: ='TABELA MASC'!J19 -> 17 | P14: ='TABELA MASC'!H19 -> 21
B15: 3 | C15: ='TABELA MASC'!H22 -> 21 | D15: ='TABELA MASC'!J22 -> 15 | F15: 3 | G15: ='TABELA MASC'!J22 -> 15 | H15: ='TABELA MASC'!H22 -> 21 | J15: 3 | K15: ='TABELA MASC'!H25 -> 18 | L15: ='TABELA MASC'!J25 -> 21 | N15: 3 | O15: ='TABELA MASC'!J25 -> 21 | P15: ='TABELA MASC'!H25 -> 18
B16: TOTAL | C16: =SUM(C13:C15) -> 63 | D16: =SUM(D13:D15) -> 44 | F16: TOTAL | G16: =SUM(G13:G15) -> 57 | H16: =SUM(H13:H15) -> 47 | J16: TOTAL | K16: =SUM(K13:K15) -> 46 | L16: =SUM(L13:L15) -> 63 | N16: TOTAL | O16: =SUM(O13:O15) -> 48 | P16: =SUM(P13:P15) -> 60
B17: MEDIA | C17: 2 | D17: =C16/D16 -> 1.4318182 | F17: MEDIA | G17: 1 | H17: =G16/H16 -> 1.212766 | J17: MEDIA | L17: =K16/L16 -> 0.73015873 | N17: MEDIA | O17: 3 | P17: =O16/P16 -> 0.8
B21: GRUPO B
B23: =GRUPOS!G11 -> FELIPE COSTA/RAPHAEL BESSA | C23: PRO | D23: CONTRA | F23: =GRUPOS!G12 -> THIAGO FELIPE/MURILO ALVES | G23: PRO | H23: CONTRA | J23: =GRUPOS!G13 -> LUCAS MENDES/FELIPE ROSSI | K23: PRO | L23: CONTRA | N23: =GRUPOS!G14 -> VINÍCIUS ALMEIDA/GUI RODRIGUES | O23: PRO | P23: CONTRA
B24: 1 | C24: ='TABELA MASC'!H11 -> 21 | D24: ='TABELA MASC'!J11 -> 15 | F24: 1 | G24: ='TABELA MASC'!H14 -> 15 | H24: ='TABELA MASC'!J14 -> 21 | J24: 1 | K24: ='TABELA MASC'!J14 -> 21 | L24: ='TABELA MASC'!H14 -> 15 | N24: 1 | O24: ='TABELA MASC'!J11 -> 15 | P24: ='TABELA MASC'!H11 -> 21
B25: 2 | C25: ='TABELA MASC'!H17 -> 18 | D25: ='TABELA MASC'!J17 -> 21 | F25: 2 | G25: ='TABELA MASC'!H20 -> 12 | H25: ='TABELA MASC'!J20 -> 21 | J25: 2 | K25: ='TABELA MASC'!J17 -> 21 | L25: ='TABELA MASC'!H17 -> 18 | N25: 2 | O25: ='TABELA MASC'!J20 -> 21 | P25: ='TABELA MASC'!H20 -> 12
B26: 3 | C26: ='TABELA MASC'!H23 -> 12 | D26: ='TABELA MASC'!J23 -> 21 | F26: 3 | G26: ='TABELA MASC'!J23 -> 21 | H26: ='TABELA MASC'!H23 -> 12 | J26: 3 | K26: ='TABELA MASC'!H26 -> 12 | L26: ='TABELA MASC'!J26 -> 21 | N26: 3 | O26: ='TABELA MASC'!J26 -> 21 | P26: ='TABELA MASC'!H26 -> 12
B27: TOTAL | C27: =SUM(C24:C26) -> 51 | D27: =SUM(D24:D26) -> 57 | F27: TOTAL | G27: =SUM(G24:G26) -> 48 | H27: =SUM(H24:H26) -> 54 | J27: TOTAL | K27: =SUM(K24:K26) -> 54 | L27: =SUM(L24:L26) -> 54 | N27: TOTAL | O27: =SUM(O24:O26) -> 57 | P27: =SUM(P24:P26) -> 45
B28: MEDIA | D28: =C27/D27 -> 0.89473684 | F28: MEDIA | H28: =G27/H27 -> 0.88888889 | J28: MEDIA | L28: =K27/L27 -> 1 | N28: MEDIA | P28: =O27/P27 -> 1.2666667
B32: GRUPO C
B34: =GRUPOS!K11 -> MATEUS LIRA/AUGUSTO | C34: PRO | D34: CONTRA | F34: =GRUPOS!K12 -> CAIO MARLEY/VAVO GUERREIRO | G34: PRO | H34: CONTRA | J34: =GRUPOS!K13 -> ENZO ALEXANDRE/ARTHUR AURÉLIO | K34: PRO | L34: CONTRA | N34: =GRUPOS!K14 -> LEONARDO/MARCUS VINÍCIUS | O34: PRO | P34: CONTRA
B35: 1 | C35: ='TABELA MASC'!H12 -> 14 | D35: ='TABELA MASC'!J12 -> 21 | F35: 1 | G35: ='TABELA MASC'!H15 -> 8 | H35: ='TABELA MASC'!J15 -> 21 | J35: 1 | K35: ='TABELA MASC'!J15 -> 21 | L35: ='TABELA MASC'!H15 -> 8 | N35: 1 | O35: ='TABELA MASC'!J12 -> 21 | P35: ='TABELA MASC'!H12 -> 14
B36: 2 | C36: ='TABELA MASC'!H18 -> 21 | D36: ='TABELA MASC'!J18 -> 18 | F36: 2 | G36: ='TABELA MASC'!H21 -> 21 | H36: ='TABELA MASC'!J21 -> 15 | J36: 2 | K36: ='TABELA MASC'!J18 -> 18 | L36: ='TABELA MASC'!H18 -> 21 | N36: 2 | O36: ='TABELA MASC'!J21 -> 15 | P36: ='TABELA MASC'!H21 -> 21
B37: 3 | C37: ='TABELA MASC'!H24 -> 18 | D37: ='TABELA MASC'!J24 -> 21 | F37: 3 | G37: ='TABELA MASC'!J24 -> 21 | H37: ='TABELA MASC'!H24 -> 18 | J37: 3 | K37: ='TABELA MASC'!H27 -> 18 | L37: ='TABELA MASC'!J27 -> 21 | N37: 3 | O37: ='TABELA MASC'!J27 -> 21 | P37: ='TABELA MASC'!H27 -> 18
B38: TOTAL | C38: =SUM(C35:C37) -> 53 | D38: =SUM(D35:D37) -> 60 | F38: TOTAL | G38: =SUM(G35:G37) -> 50 | H38: =SUM(H35:H37) -> 54 | J38: TOTAL | K38: =SUM(K35:K37) -> 57 | L38: =SUM(L35:L37) -> 50 | N38: TOTAL | O38: =SUM(O35:O37) -> 57 | P38: =SUM(P35:P37) -> 53
B39: MEDIA | D39: =C38/D38 -> 0.88333333 | F39: MEDIA | H39: =G38/H38 -> 0.92592593 | J39: MEDIA | L39: =K38/L38 -> 1.14 | N39: MEDIA | P39: =O38/P38 -> 1.0754717
B43: CLASSIFICADOS
B44: POSIÇÃO | C44: DUPLA | K44: VITÓRIAS | M44: CLASSIFICAÇÃO NO GRUPO | O44: AVERAGE
B45: 1º
B46: 2º
B47: 3º
B48: 4º
B49: 5º
B50: 6º
B51: 7º
B52: 8º
F55: RASCUNHO | I55: DUPLA | K55: VITÓRIAS | M55: CLASSIFICAÇÃO NO GRUPO | O55: AVERAGE
