Workbook
Name FromArray_1: _xlfn.ANCHORARRAY(#REF!)

Sheet REGULAMENTO
B2: Circuito NCT Vôlei de Praia 2026
B3: 1ª Etapa (Arena Caffe)
B4: 🏐 Intermediário Feminino 🏐
B5: REGULAMENTO
B7: 📍 CHECK-IN DO TORNEIO | DADOS TÉCNICOS
B8: DATA: 24/05/2026 (Domingo) às 7h30 (início dos Jogos 1 e 2 às 8h)
B9: LOCAL: Arena Caffe (Gama) 📍 localização anexada no grupo de Whatsapp
B10: FORMATO: 16 Duplas | 32 Partidas | 4 Grupos de 4 duplas | 2 Quadras
B11: SET: Único de 21 pontos (exceto Final 2)
B13: 🏐 FASE DE GRUPOS:
B14: Formato: todos contra todos
B15: Classificação: somente as 2 (duas) melhores duplas de cada grupo
... B18: O chaveamento dos playoffs (do 1º ao 8º colocado) será estruturado da seguinte forma:
B19: Blocos | D19: A: 1º, 8º, 4º e 5º Geral | H19: B: 2º, 7º, 3º e 6º Geral
B20: Critérios de Desempate para: | D20: 1º | E20: Número de vitórias
D21: 2º | E21: Ponto Average
B22: Fase de grupo e Classificação geral | D22: 3º | E22: Confronto direto
D23: 4º | E23: Sorteio (cara ou coroa)
B24: ⚠️ Nota: | C24: Na classificação geral, segue-se os critérios acima, independente da posição conquistada no grupo.
B26: 🔥 CHAVEAMENTO (MATA-MATA)
B27: BLOCO A | C27: · J25: 1º GERAL vs 8º GERAL | F27: · J26: 4º GERAL vs 5º GERAL | I27: · SEMIFINAL 1: V. J25 x V. J26
B28: BLOCO B | C28: · J27: 2º GERAL vs 7º GERAL | F28: · J28: 3º GERAL vs 6º GERAL | I28: · SEMIFINAL 2: V. J27 x V. J28
B29: · FINAL 1: Bronze (Perdedores das semifinais) | G29: · FINAL 2: Ouro e Prata (Vencedores das seminifinais)
B31: 📜 REGRAS DE CONDUTA E TÉCNICA
B32: W.O. & DESISTÊNCIA: No W.O, vitória da dupla presente, sem saldo de pontos. Em desistência, placar de 21 (ou dif. de 2) para quem ficou mantendo-se o placar do desistente.
B33: CLIMA/INTERRUPÇÃO: Até 4h de pausa, mantém o placar. Após 4h, reinício (0x0).
B34: UNIFORME: Camiseta NCT Temporada 2026 (Obrigatória). Bermudas iguais (Preferencial).
B35: DISCIPLINA: Tolerância zero para violência ou desrespeito. Sujeito a banimento imediato.
B37: 📈 PONTUAÇÃO RANKING NCT (Individual) | I37: 🏆 PREMIAÇÃO
B38: 🥇 1º | C38: 🥈 2º | D38: 🥉 3º | E38: 🏅 4º | F38: 🎖️ 5º a 8º | G38: 🎖️ 9º a 16º | I38: 1º ao 4º lugar
B39: 300 | C39: 240 | D39: 190 | E39: 150 | F39: 120 | G39: 100 | I39: Troféus

Sheet GRUPOS
B2: Circuito NCT Vôlei de Praia 2026
B3: 1ª Etapa (Arena Caffe)
B4: GRUPOS ( Intermediário Feminino)
B5: Distribuição pelo ranking no modo serpentina
B7: GRUPO A | F7: GRUPO B | J7: GRUPO C | N7: GRUPO D
B8: RK | C8: DUPLA | D8: CÓD | F8: RK | G8: DUPLA | H8: CÓD | J8: RK | K8: DUPLA | L8: CÓD | N8: RK | O8: DUPLA | P8: CÓD
B9: 1º | C9: =C18 -> Brunele N./Milena Menezes | D9: A1 | F9: 2º | G9: =C19 -> Luana/Juliane | H9: B1 | J9: 3º | K9: =C20 -> Camila/Fabi | L9: C1 | N9: 4º | O9: =C21 -> Julli/Rayanne | P9: D1
B10: 8º | C10: =C25 -> Alciene/Marina | D10: A2 | F10: 7º | G10: =C24 -> Fran/Karu | H10: B2 | J10: 6º | K10: =C23 -> Sergi/Suzi | L10: C2 | N10: 5º | O10: =C22 -> Sarah/Marina Santos | P10: D2 | T10: Ordem do sorteio
B11: 9º | C11: =K18 -> Dani Costa/Lígia | D11: A3 | F11: 10º | G11: =K19 -> Juliana/Bruna Caltabiano | H11: B3 | J11: 11º | K11: =K20 -> Iza/Ray | L11: C3 | N11: 12º | O11: =K21 -> Lili/Gadelha | P11: D3 | T11: Brunele Noronha/Milena Menezes
B12: 16º | C12: =K25 -> Isabela Monteiro/Marina Vasc. | D12: A4 | F12: 15º | G12: =K24 -> ⁠Manu Gomes/Julia Evelyn | H12: B4 | J12: 14º | K12: =K23 -> Tata Bonini/Duda Rocha | L12: C4 | N12: 13º | O12: =K22 -> Rafa Silva/Julia Klin | P12: D4 | T12: Luana/Juliane
T13: Camila/Fabi
T14: Julli/Rayanne
B15: Ranking Sorteado | T15: Sarah/Marina Santos
T16: Sergi/Suzi
B17: RK | C17: Dupla | H17: CÓD | J17: RK | K17: Dupla | P17: CÓD | T17: Fran/Karu
B18: 1º | C18: Brunele N./Milena Menezes | F18: Sorteio | H18: A1 | J18: 9º | K18: Dani Costa/Lígia | N18: Sorteio | P18: A3 | T18: Alciene/Marina
B19: 2º | C19: Luana/Juliane | F19: Sorteio | H19: B1 | J19: 10º | K19: Juliana/Bruna Caltabiano | N19: Sorteio | P19: B3 | T19: Dani Costa/Lígia
B20: 3º | C20: Camila/Fabi | F20: Sorteio | H20: C1 | J20: 11º | K20: Iza/Ray | N20: Sorteio | P20: C3 | T20: Juliana/Bruna Caltabiano
B21: 4º | C21: Julli/Rayanne | F21: Sorteio | H21: D1 | J21: 12º | K21: Lili/Gadelha | N21: Sorteio | P21: D3 | T21: Iza/Ray
B22: 5º | C22: Sarah/Marina Santos | F22: Sorteio | H22: D2 | J22: 13º | K22: Rafa Silva/Julia Klin | N22: Sorteio | P22: D4 | T22: Lili/Gadelha
B23: 6º | C23: Sergi/Suzi | F23: Sorteio | H23: C2 | J23: 14º | K23: Tata Bonini/Duda Rocha | N23: Sorteio | P23: C4 | T23: Rafa Silva/Julia Klin
B24: 7º | C24: Fran/Karu | F24: Sorteio | H24: B2 | J24: 15º | K24: ⁠Manu Gomes/Julia Evelyn | N24: Sorteio | P24: B4 | T24: Tata Bonini/Duda Rocha
B25: 8º | C25: Alciene/Marina | F25: Sorteio | H25: A2 | J25: 16º | K25: Isabela Monteiro/Marina Vasc. | N25: Sorteio | P25: A4 | T25: ⁠Manu Gomes/Julia Evelyn
T26: Isabela Monteiro/Marina Vasconcelos

Sheet TABELA_AVERAGE
B2: Circuito NCT Vôlei de Praia 2026
B3: 1ª Etapa (Arena Caffe)
B4: 🏐 Intermediário Feminino 🏐
B5: TABELA | P5: Average
AC6: Legenda:
B7: FASE DE GRUPOS | P7: GRUPO A | R7: Partidas | X7: Ponto Average | AC7: PP | AD7: Pontos Pró
B8: Jogo | C8: Grupo | D8: Hora | E8: Quadra | F8: Código | G8: Equipe 1 | K8: Equipe 2 | L8: Código | R8: PP | S8: PC | T8: PP | U8: PC | V8: PP | W8: PC | X8: TPP | Y8: TPC | Z8: Score | AC8: PC | AD8: Pontos Contra
B9: 1 | C9: A | D9: 8:00 | F9: A1 | G9: =GRUPOS!C9 -> Brunele N./Milena Menezes | I9: X | K9: =GRUPOS!C12 -> Isabela Monteiro/Marina Vasc. | L9: A4 | P9: A1 | Q9: =GRUPOS!C18 -> Brunele N./Milena Menezes | R9: =H9 -> 0 | S9: =J9 -> 0 | T9: =H17 -> 0 | U9: =J17 -> 0 | V9: =H25 -> 0 | W9: =J25 -> 0 | X9: =R9+T9+V9 -> 0 | Y9: =S9+U9+W9 -> 0 | Z9: =X9/Y9 -> #DIV/0! | AC9: TPP | AD9: Total Pontos Pró
B10: 2 | C10: B | D10: 8:00 | F10: B1 | G10: =GRUPOS!G9 -> Luana/Juliane | I10: X | K10: =GRUPOS!G12 -> ⁠Manu Gomes/Julia Evelyn | L10: B4 | P10: A2 | Q10: =GRUPOS!C25 -> Alciene/Marina | R10: =H13 -> 0 | S10: =J13 -> 0 | T10: =H21 -> 0 | U10: =J21 -> 0 | V10: =J25 -> 0 | W10: =H25 -> 0 | X10: =R10+T10+V10 -> 0 | Y10: =S10+U10+W10 -> 0 | Z10: =X10/Y10 -> #DIV/0! | AC10: TPF | AD10: Total Pontos Contra
B11: 3 | C11: C | D11: 8:20 | F11: C1 | G11: =GRUPOS!K9 -> Camila/Fabi | I11: X | K11: =GRUPOS!K12 -> Tata Bonini/Duda Rocha | L11: C4 | P11: A3 | Q11: =GRUPOS!K18 -> Dani Costa/Lígia | R11: =J13 -> 0 | S11: =H13 -> 0 | T11: =J17 -> 0 | U11: =H17 -> 0 | V11: =H29 -> 0 | W11: =J29 -> 0 | X11: =R11+T11+V11 -> 0 | Y11: =S11+U11+W11 -> 0 | Z11: =X11/Y11 -> #DIV/0!
B12: 4 | C12: D | D12: 8:20 | F12: D1 | G12: =GRUPOS!O9 -> Julli/Rayanne | I12: X | K12: =GRUPOS!O12 -> Rafa Silva/Julia Klin | L12: D4 | P12: A4 | Q12: =GRUPOS!K25 -> Isabela Monteiro/Marina Vasc. | R12: =J9 -> 0 | S12: =H9 -> 0 | T12: =J21 -> 0 | U12: =H21 -> 0 | V12: =J29 -> 0 | W12: =H29 -> 0 | X12: =R12+T12+V12 -> 0 | Y12: =S12+U12+W12 -> 0 | Z12: =X12/Y12 -> #DIV/0!
B13: 5 | C13: A | D13: 8:40 | F13: A2 | G13: =GRUPOS!C10 -> Alciene/Marina | I13: X | K13: =GRUPOS!C11 -> Dani Costa/Lígia | L13: A3
B14: 6 | C14: B | D14: 8:40 | F14: B2 | G14: =GRUPOS!G10 -> Fran/Karu | I14: X | K14: =GRUPOS!G11 -> Juliana/Bruna Caltabiano | L14: B3 | P14: GRUPO B | R14: Partidas | X14: Ponto Average
B15: 7 | C15: C | D15: 9:00 | F15: C2 | G15: =GRUPOS!K10 -> Sergi/Suzi | I15: X | K15: =GRUPOS!K11 -> Iza/Ray | L15: C3 | R15: PP | S15: PC | T15: PP | U15: PC | V15: PP | W15: PC | X15: TPP | Y15: TPC | Z15: Score
B16: 8 | C16: D | D16: 9:00 | F16: D2 | G16: =GRUPOS!O10 -> Sarah/Marina Santos | I16: X | K16: =GRUPOS!O11 -> Lili/Gadelha | L16: D3 | P16: B1 | Q16: =GRUPOS!C19 -> Luana/Juliane | R16: =H10 -> 0 | S16: =J10 -> 0 | T16: =H18 -> 0 | U16: =J18 -> 0 | V16: =H26 -> 0 | W16: =J26 -> 0 | X16: =R16+T16+V16 -> 0 | Y16: =S16+U16+W16 -> 0 | Z16: =X16/Y16 -> #DIV/0!
B17: 9 | C17: A | D17: 9:20 | F17: A1 | G17: =GRUPOS!C9 -> Brunele N./Milena Menezes | I17: X | K17: =GRUPOS!C11 -> Dani Costa/Lígia | L17: A3 | P17: B2 | Q17: =GRUPOS!C24 -> Fran/Karu | R17: =H14 -> 0 | S17: =J14 -> 0 | T17: =H22 -> 0 | U17: =J22 -> 0 | V17: =J26 -> 0 | W17: =H26 -> 0 | X17: =R17+T17+V17 -> 0 | Y17: =S17+U17+W17 -> 0 | Z17: =X17/Y17 -> #DIV/0!
B18: 10 | C18: B | D18: 9:20 | F18: B1 | G18: =GRUPOS!G9 -> Luana/Juliane | I18: X | K18: =GRUPOS!G11 -> Juliana/Bruna Caltabiano | L18: B3 | P18: B3 | Q18: =GRUPOS!K19 -> Juliana/Bruna Caltabiano | R18: =J14 -> 0 | S18: =H14 -> 0 | T18: =J18 -> 0 | U18: =H18 -> 0 | V18: =H30 -> 0 | W18: =J30 -> 0 | X18: =R18+T18+V18 -> 0 | Y18: =S18+U18+W18 -> 0 | Z18: =X18/Y18 -> #DIV/0!
B19: 11 | C19: C | D19: 9:40 | F19: C1 | G19: =GRUPOS!K9 -> Camila/Fabi | I19: X | K19: =GRUPOS!K11 -> Iza/Ray | L19: C3 | P19: B4 | Q19: =GRUPOS!K24 -> ⁠Manu Gomes/Julia Evelyn | R19: =J10 -> 0 | S19: =H10 -> 0 | T19: =J22 -> 0 | U19: =H22 -> 0 | V19: =J30 -> 0 | W19: =H30 -> 0 | X19: =R19+T19+V19 -> 0 | Y19: =S19+U19+W19 -> 0 | Z19: =X19/Y19 -> #DIV/0!
B20: 12 | C20: D | D20: 9:40 | F20: D1 | G20: =GRUPOS!O9 -> Julli/Rayanne | I20: X | K20: =GRUPOS!O11 -> Lili/Gadelha | L20: D3
B21: 13 | C21: A | D21: 10:00 | F21: A2 | G21: =GRUPOS!C10 -> Alciene/Marina | I21: X | K21: =GRUPOS!C12 -> Isabela Monteiro/Marina Vasc. | L21: A4 | P21: GRUPO C | R21: Partidas | X21: Ponto Average
B22: 14 | C22: B | D22: 10:20 | F22: B2 | G22: =GRUPOS!G10 -> Fran/Karu | I22: X | K22: =GRUPOS!G12 -> ⁠Manu Gomes/Julia Evelyn | L22: B4 | R22: PP | S22: PC | T22: PP | U22: PC | V22: PP | W22: PC | X22: TPP | Y22: TPC | Z22: Score
B23: 15 | C23: C | D23: 10:40 | F23: C2 | G23: =GRUPOS!K10 -> Sergi/Suzi | I23: X | K23: =GRUPOS!K12 -> Tata Bonini/Duda Rocha | L23: C4 | P23: C1 | Q23: =GRUPOS!C20 -> Camila/Fabi | R23: =H11 -> 0 | S23: =J11 -> 0 | T23: =H19 -> 0 | U23: =J19 -> 0 | V23: =H27 -> 0 | W23: =J27 -> 0 | X23: =R23+T23+V23 -> 0 | Y23: =S23+U23+W23 -> 0 | Z23: =X23/Y23 -> #DIV/0!
B24: 16 | C24: D | D24: 11:00 | F24: D2 | G24: =GRUPOS!O10 -> Sarah/Marina Santos | I24: X | K24: =GRUPOS!O12 -> Rafa Silva/Julia Klin | L24: D4 | P24: C2 | Q24: =GRUPOS!C23 -> Sergi/Suzi | R24: =H15 -> 0 | S24: =J15 -> 0 | T24: =H23 -> 0 | U24: =J23 -> 0 | V24: =J27 -> 0 | W24: =H27 -> 0 | X24: =R24+T24+V24 -> 0 | Y24: =S24+U24+W24 -> 0 | Z24: =X24/Y24 -> #DIV/0!
B25: 17 | C25: A | D25: 11:20 | F25: A1 | G25: =GRUPOS!C9 -> Brunele N./Milena Menezes | I25: X | K25: =GRUPOS!C10 -> Alciene/Marina | L25: A2 | P25: C3 | Q25: =GRUPOS!K20 -> Iza/Ray | R25: =J15 -> 0 | S25: =H15 -> 0 | T25: =J19 -> 0 | U25: =H19 -> 0 | V25: =H31 -> 0 | W25: =J31 -> 0 | X25: =R25+T25+V25 -> 0 | Y25: =S25+U25+W25 -> 0 | Z25: =X25/Y25 -> #DIV/0!
B26: 18 | C26: B | D26: 11:40 | F26: B1 | G26: =GRUPOS!G9 -> Luana/Juliane | I26: X | K26: =GRUPOS!G10 -> Fran/Karu | L26: B2 | P26: C4 | Q26: =GRUPOS!K23 -> Tata Bonini/Duda Rocha | R26: =J11 -> 0 | S26: =H11 -> 0 | T26: =J23 -> 0 | U26: =H23 -> 0 | V26: =J31 -> 0 | W26: =H31 -> 0 | X26: =R26+T26+V26 -> 0 | Y26: =S26+U26+W26 -> 0 | Z26: =X26/Y26 -> #DIV/0!
B27: 19 | C27: C | D27: 12:00 | F27: C1 | G27: =GRUPOS!K9 -> Camila/Fabi | I27: X | K27: =GRUPOS!K10 -> Sergi/Suzi | L27: C2
B28: 20 | C28: D | D28: 12:20 | F28: D1 | G28: =GRUPOS!O9 -> Julli/Rayanne | I28: X | K28: =GRUPOS!O10 -> Sarah/Marina Santos | L28: D2 | P28: GRUPO D | R28: Partidas | X28: Ponto Average
B29: 21 | C29: A | D29: 12:40 | F29: A3 | G29: =GRUPOS!C11 -> Dani Costa/Lígia | I29: X | K29: =GRUPOS!C12 -> Isabela Monteiro/Marina Vasc. | L29: A4 | R29: PP | S29: PC | T29: PP | U29: PC | V29: PP | W29: PC | X29: TPF | Y29: TPP | Z29: Score
B30: 22 | C30: B | D30: 13:00 | F30: B3 | G30: =GRUPOS!G11 -> Juliana/Bruna Caltabiano | I30: X | K30: =GRUPOS!G12 -> ⁠Manu Gomes/Julia Evelyn | L30: B4 | P30: D1 | Q30: =GRUPOS!C21 -> Julli/Rayanne | R30: =H12 -> 0 | S30: =J12 -> 0 | T30: =H20 -> 0 | U30: =J20 -> 0 | V30: =H28 -> 0 | W30: =J28 -> 0 | X30: =R30+T30+V30 -> 0 | Y30: =S30+U30+W30 -> 0 | Z30: =X30/Y30 -> #DIV/0!
B31: 23 | C31: C | D31: 13:20 | F31: C3 | G31: =GRUPOS!K11 -> Iza/Ray | I31: X | K31: =GRUPOS!K12 -> Tata Bonini/Duda Rocha | L31: C4 | P31: D2 | Q31: =GRUPOS!C22 -> Sarah/Marina Santos | R31: =H16 -> 0 | S31: =J16 -> 0 | T31: =H24 -> 0 | U31: =J24 -> 0 | V31: =J28 -> 0 | W31: =H28 -> 0 | X31: =R31+T31+V31 -> 0 | Y31: =S31+U31+W31 -> 0 | Z31: =X31/Y31 -> #DIV/0!
B32: 24 | C32: D | D32: 13:40 | F32: D3 | G32: =GRUPOS!O11 -> Lili/Gadelha | I32: X | K32: =GRUPOS!O12 -> Rafa Silva/Julia Klin | L32: D4 | P32: D3 | Q32: =GRUPOS!K21 -> Lili/Gadelha | R32: =J16 -> 0 | S32: =H16 -> 0 | T32: =J20 -> 0 | U32: =H20 -> 0 | V32: =H32 -> 0 | W32: =J32 -> 0 | X32: =R32+T32+V32 -> 0 | Y32: =S32+U32+W32 -> 0 | Z32: =X32/Y32 -> #DIV/0!
P33: D4 | Q33: =GRUPOS!K22 -> Rafa Silva/Julia Klin | R33: =J12 -> 0 | S33: =H12 -> 0 | T33: =J24 -> 0 | U33: =H24 -> 0 | V33: =J32 -> 0 | W33: =H32 -> 0 | X33: =R33+T33+V33 -> 0 | Y33: =S33+U33+W33 -> 0 | Z33: =X33/Y33 -> #DIV/0!
B34: QUARTAS DE FINAL
B35: 25 | C35: QF1 | D35: 14:00 | F35: 1G | G35: =R37 -> 1º Geral | I35: X | K35: =R44 -> 8º Geral | L35: 8G | P35: CLASSIFICAÇÃO GERAL
B36: 26 | C36: QF2 | D36: 14:00 | F36: 4G | G36: =R40 -> 4º Geral | I36: X | K36: =R41 -> 5º Geral | L36: 5G | P36: Ordem | Q36: Grupo | R36: Dupla | Z36: P. Average
B37: 27 | C37: QF3 | D37: 14:20 | F37: 2G | G37: =R38 -> 2º Geral | I37: X | K37: =R43 -> 7º Geral | L37: 7G | P37: 1º | R37: 1º Geral
B38: 28 | C38: QF4 | D38: 14:20 | F38: 3G | G38: =R39 -> 3º Geral | I38: X | K38: =R42 -> 6º Geral | L38: 6G | P38: 2º | R38: 2º Geral
P39: 3º | R39: 3º Geral
B40: SEMIFINAIS | P40: 4º | R40: 4º Geral
B41: 29 | C41: SF1 | D41: 14:40 | F41: VJ25 | G41: Venc. Jogo 25 | I41: X | K41: Venc. Jogo 26 | L41: VJ26 | P41: 5º | R41: 5º Geral
...
