Workbook
Name FromArray_1: _xlfn.ANCHORARRAY(#REF!)
Name FromArray_1: _xlfn.ANCHORARRAY(#REF!)
Name FromArray_1: _xlfn.ANCHORARRAY(#REF!)

Sheet RANKING 2025
B2: CIRCUITO NCT VÔLEI DE PRAIA - 2025
B3: INICIANTE MASCULINO
B4: RANKING
B5: Rk | C5: Atleta | D5: Nome Completo | E5: Centro de Treinamento | F5: UF | G5: 1ª Etapa | H5: 2ª Etapa | I5: 3ª Etapa | J5: 4ª Etapa | K5: 5ª Etapa | L5: Total
G6: Arena Caffe | H6: Parque da Cidade | I6: Vamo Beach | J6: Arena 61 | K6: Parque da Cidade
B7: 1 | C7: DUDU SANTOS 👑 | D7: Josualdo Oliveira Santos | E7: Não tem | F7: DF | G7: 200 | H7: 180 | I7: 180 | J7: 180 | K7: 120 | L7: =SUM(G7:K7) -> 860
C8: THAYUAN 👑 | D8: Thayuan Silva Yamada | E8: Não tem | F8: DF | G8: 200 | H8: 180 | I8: 180 | J8: 180 | K8: 120 | L8: =SUM(G8:K8) -> 860
B9: 2 | C9: JEAN | D9: Jean Carlos Gomes de Araújo | E9: M2 (Arena 61) | F9: DF | G9: 120 | H9: 120 | I9: 160 | J9: 160 | K9: 160 | L9: =SUM(G9:K9) -> 720
B10: 3 | C10: ANTÔNIO | D10: Antônio Carlos Gouveia do Nascimento | E10: CTEN (NIPO) | F10: DF | G10: 0 | H10: 200 | I10: 0 | J10: 200 | K10: 180 | L10: =SUM(G10:K10) -> 580
B11: 4 | C11: ÁTILA | D11: Átila Sobral de Oliveira | E11: M2 (Arena 61) | F11: DF | G11: 180 | H11: 0 | I11: 200 | J11: 140 | K11: 0 | L11: =SUM(G11:K11) -> 520
B12: 5 | C12: KAKA | D12: Carlos Daniel Fernandes de Lima | E12: M2 (Arena 61) | F12: DF | G12: 0 | H12: 120 | I12: 140 | J12: 0 | K12: 160 | L12: =SUM(G12:K12) -> 420
B13: 6 | C13: JOWJOW | D13: Joaran Moura Marques | E13: CT Beats | F13: DF | G13: 140 | H13: 140 | I13: 120 | J13: 0 | K13: 0 | L13: =SUM(G13:K13) -> 400
B14: 7 | C14: CADU SANTOS | D14: Carlos Eduardo Morais dos Santos | E14: M2 (Arena 61) | F14: DF | G14: 180 | H14: 0 | I14: 200 | J14: 0 | K14: 0 | L14: =SUM(G14:K14) -> 380
B15: 8 | C15: GEO | D15: Geovane Rodrigues da Mota | E15: M2 (Arena 61) | F15: DF | G15: 120 | H15: 120 | I15: 140 | J15: 0 | K15: 0 | L15: =SUM(G15:K15) -> 380
B16: 9 | C16: BERNA | D16: Bernardo Guedes Ribeiro | E16: M2 (Arena 61) | F16: DF | G16: 120 | H16: 120 | I16: 0 | J16: 120 | K16: 0 | L16: =SUM(G16:K16) -> 360
B17: 10 | C17: DUUH | D17: Paulo Eduardo Gomes dos Santos | E17: M2 (Arena 61) | F17: DF | G17: 120 | H17: 100 | I17: 0 | J17: 0 | K17: 120 | L17: =SUM(G17:K17) -> 340
B18: 11 | C18: DUDU CASTRO | D18: Luiz Eduardo de Castro Almeida | E18: M2 (Arena 61) | F18: DF | G18: 0 | H18: 0 | I18: 160 | J18: 160 | K18: 0 | L18: =SUM(G18:K18) -> 320
B19: 12 | C19: OLAVO | D19: Olavo Oliveira Braga Neto | E19: Fitvôlei Nação | F19: DF | G19: 140 | H19: 140 | I19: 0 | J19: 0 | K19: 0 | L19: =SUM(G19:K19) -> 280
C20: PEDRO AUGUSTO | D20: Pedro Augusto Cardoso | E20: NCT (Vamo Beach) | F20: DF | G20: 0 | H20: 0 | I20: 0 | J20: 140 | K20: 140 | L20: =SUM(G20:K20) -> 280
B21: 13 | C21: MATEUS ALVES | D21: Matheus Alves Martos | E21: M2 (Arena 61) | F21: DF | G21: 0 | H21: 0 | I21: 120 | J21: 140 | K21: 0 | L21: =SUM(G21:K21) -> 260
B22: 14 | C22: THOMÁS | D22: Thomás Andrade se Souto | E22: M2 (Arena 61) | F22: DF | G22: 120 | H22: 120 | I22: 0 | J22: 0 | K22: 0 | L22: =SUM(G22:K22) -> 240
B23: 15 | C23: FERNANDO G. | D23: Fernando de Almeida Guimarães | E23: Fitvôlei Nação | F23: DF | G23: 100 | H23: 0 | I23: 120 | J23: 0 | K23: 0 | L23: =SUM(G23:K23) -> 220
C24: MICHAEL | D24: Michael Lago | E24: M2 (Arena 61) | F24: DF | G24: 120 | H24: 100 | I24: 0 | J24: 0 | K24: 0 | L24: =SUM(G24:K24) -> 220
C25: DIEGO TENÓRIO | D25: Diego Tenorio Gomes | E25: NCT (Arena Caffe) | F25: DF | G25: 0 | H25: 100 | I25: 0 | J25: 120 | K25: 0 | L25: =SUM(G25:K25) -> 220
B26: 16 | C26: ADRIANO | D26: Adriano Marcio de Oliveira Flausino Filho | E26: Fitvôlei Nação | F26: DF | G26: 0 | H26: 0 | I26: 0 | J26: 0 | K26: 200 | L26: =SUM(G26:K26) -> 200
C27: MARCUS VINÍCIUS | D27: Marcus Vinicius Barreto de Macedo | E27: Fitvôlei Nação | F27: DF | G27: 0 | H27: 0 | I27: 0 | J27: 0 | K27: 200 | L27: =SUM(G27:K27) -> 200
C28: MATEUS REIS | D28: Mateus de Andrade Rodrigues Reis | E28: Não tem | F28: DF | G28: 0 | H28: 200 | I28: 0 | J28: 0 | K28: 0 | L28: =SUM(G28:K28) -> 200
C29: RODRIGO FIDELIS | D29: Rodrigo Barcellos Fidelis | E29: CTEN (NIPO) | F29: DF | G29: 0 | H29: 0 | I29: 0 | J29: 200 | K29: 0 | L29: =SUM(G29:K29) -> 200
B30: 17 | C30: DAN | D30: Daniel Souza de Santana | E30: Não tem | F30: DF | G30: 100 | H30: 100 | I30: 0 | J30: 0 | K30: 0 | L30: =SUM(G30:K30) -> 200
C31: ERIK | D31: Erik Lopes da Silva | E31: Não tem | F31: DF | G31: 100 | H31: 100 | I31: 0 | J31: 0 | K31: 0 | L31: =SUM(G31:K31) -> 200
B32: 18 | C32: LEONARDO | D32: Leonardo Teixeira Sá Freire de Abreu | E32: Fitvôlei Nação | F32: DF | G32: 0 | H32: 0 | I32: 0 | J32: 0 | K32: 180 | L32: =SUM(G32:K32) -> 180
B33: 19 | C33: CÉSAR | D33: César Augusto Tavares da Silva | E33: Não tem | F33: DF | G33: 160 | H33: 0 | I33: 0 | J33: 0 | K33: 0 | L33: =SUM(G33:K33) -> 160
C34: GABRIEL | D34: Gabriel Santos Horst de Oliveira | E34: PPDF | F34: DF | G34: 0 | H34: 160 | I34: 0 | J34: 0 | K34: 0 | L34: =SUM(G34:K34) -> 160
C35: HENRIQUE LINHARES | D35: Henrique da Câmara Linhares | E35: CBMDF | F35: DF | G35: 0 | H35: 160 | I35: 0 | J35: 0 | K35: 0 | L35: =SUM(G35:K35) -> 160
C36: LUCAS SILVA | D36: Lucas Silva Pereira Rosa | E36: Não tem | F36: DF | G36: 160 | H36: 0 | I36: 0 | J36: 0 | K36: 0 | L36: =SUM(G36:K36) -> 160
B37: 20 | C37: MARCELLO | D37: Paulo Marcello Aragão Leite | E37: NCT (Vamo Beach) | F37: DF | G37: 0 | H37: 0 | I37: 0 | J37: 0 | K37: 140 | L37: =SUM(G37:K37) -> 140
B38: 21 | C38: AISLAN BARBOSA | D38: Aislan Barbosa de Oliveira | E38: Asas | F38: DF | G38: 0 | H38: 0 | I38: 0 | J38: 120 | K38: 0 | L38: =SUM(G38:K38) -> 120
C39: ALAN | D39: Alan Carlos Brandão | E39: Luziânia | F39: GO | G39: 0 | H39: 0 | I39: 0 | J39: 120 | K39: 0 | L39: =SUM(G39:K39) -> 120
C40: ALCIDES | D40: Alcides Nicolas Silva Santos | E40: Não tem | F40: DF | G40: 0 | H40: 0 | I40: 120 | J40: 0 | K40: 0 | L40: =SUM(G40:K40) -> 120
C41: ARTHUR | D41: Arthur Ataíde Medeiros | E41: M2 (Arena 61) | F41: DF | G41: 0 | H41: 0 | I41: 120 | J41: 0 | K41: 0 | L41: =SUM(G41:K41) -> 120
...

Sheet REGULAMENTO IM
B2: CIRCUITO NCT VÔLEI DE PRAIA - 2025
B4: REGULAMENTO
B6: 5ª Etapa | D6: INICIANTE MASCULINO | H6: 06/12/2025
B7: Parque da Cidade | H7: sábado
B9: item | C9: Título | D9: Descrição | H9: Observação
B10: 1 | C10: Ranking de entrada | D10: Ranking 2025. Nos casos de empate, prevalecerá a equipe que tiver a maior quantidade de melhores posições. P. ex.: o empate em pontos entre duplas será resolvido a favor da dupla que tem o maior número de 1º lugares, 2º, etc, e assim sucessivamente. Permancendo o empate, haverá sorteio.
B11: 2 | C11: Distribuição dos grupos | D11: Modelo de serpentina seguindo ranking 2025.
B12: 3 | C12: Quantidade de duplas | D12: 8 duplas (16 atletas).
B13: 4 | C13: Quantidade de jogos | D13: 18 partidas.
B14: 5 | C14: Quantidade de sets* | D14: 1 Set de 21 pontos. | H14: *Exceto a final 2.
B15: 6 | C15: Sistema de disputa da 1ª fase | D15: Todos contra todos no grupo. | H15: 3 jogos por equipe.
B16: 7 | C16: Critérios de desempate para definição de posições no grupo | D16: 1º - nº de vitórias.
D17: 2º - ponto average.
D18: 3º - confronto direto.
D19: 4º - sorteio.
B20: 8 | C20: Classificação direta para as semifinais | D20: Classifica-se o primeiro colocado de cada grupo diretamente para as semifinais.
B21: 9 | C21: Quartas-de-final | D21: Classificam-se os segundos e terceiros colocados de cada grupo com o seguinte cruzamento:
D22: 2A x 3B ------------------ 2B X 3A
B23: 10 | C23: Semifinais | D23: 1B X Vencedor: 2A X 3B
D24: 1A X Vencedor: 2B X 3A
B25: 11 | C25: Final 1 (disputa pelo 3º lugar) | D25: Jogo entre os perdedores das semifinais: 1 Set de 21 pontos.
B26: 12 | C26: Final 2: (disputa pelo 1º lugar) | D26: Jogo entre os vencedores das semifinais: 2 sets de 21 pontos e set desempate de 15 pontos.
B27: 13 | C27: Pontuação em Wx0 | D27: As partidas resolvidas pela não apresentação de uma dupla resultará na vitória da dupla que se apresentou, contudo, não haverá saldo de pontos para nenhuma das duplas envolvidas. No caso de duplo W x 0, as duas duplas serão consideradas derrotadas e, consequentemente, sem saldo de pontos.
B28: 14 | C28: Pontuação em partida abandonada por desistência | D28: As partidas em que uma dupla desistir de continuar a partida, terá o placar de 21 (ou diferença de 2 pontos) para a equipe que não desistiu. A dupla que desistiu permanece com a pontuação do momento da desistência.
B29: 15 | C29: Pontuação no Ranking | D29: A distribuição de pontos por atleta ao final de cada etapa se dará da seguinte forma:
D30: 1º lugar: 200 / 2º lugar: 180 / 3º lugar: 160 / 4º lugar: 140 / 5º lugar: 120 / 9º lugar: 100.
B31: 16 | C31: Penalidades | D31: A atleta que agir com desrespeito e violência em relação à arbitragem, adversários, parceiro e qualquer pessoa presente, poderá ser suspenso ou banido do Circuito NCT por deliberação da Comissão Organizadora.
B32: 17 | C32: Suspensão de partidas | D32: As partidas que precisarem ser suspensas por motivos de mau tempo, falta de iluminação e assemelhados, retornará com o placar da interrupção, caso isso ocorra em até 4 horas. Após isso, a partida recomeçará com o placar de 0x0.
B33: 18 | C33: Uniformização | D33: Camiseta oficial do Circuito NCT Vôlei de Praia 2025. | H33: Obrigatória.
D34: Bermudas da mesma cor. | H34: Preferencialmente.
B35: 19 | C35: Horário de início | D35: 8h, em DUAS quadras.
B36: 20 | C36: Local da competição | D36: Parque da Cidade Sarah Kubitschek (próximo à ADM) - Localização compartilhada no grupo de whatsapp

Sheet GRUPOS
B2: CIRCUITO NCT VÔLEI DE PRAIA - 2025
B3: 5ª Etapa - Parque da Cidade
B4: INICIANTE MASCULINO
B5: 6 de dezembro de 2025 - sábado
B6: GRUPOS
B7: Distribuição pelo ranking no modo serpentina
B9: GRUPO A | F9: GRUPO B
B10: RANKING | C10: DUPLA | F10: RANKING | G10: DUPLA
B11: 1º | C11: =C17 -> DUDU SANTOS/THAYUAN | F11: 2º | G11: =C18 -> JEAN/KAKÁ
B12: 4º | C12: =C20 -> DUUH/ÍTALO | F12: 3º | G12: =C19 -> ANTÔNIO/LEONARDO | K12: CLASSIFICAÇÃO FINAL | O12: TOTAL
B13: 5º | C13: =G17 -> PEDRO/MARCELLO | F13: 6º | G13: =G18 -> ADRIANO/MARCUS VINÍCIUS | K13: 1º | L13: DUDU SANTOS/THAYUAN | M13: 740 | N13: 740 | O13: =SUM(M13:N13) -> 1480 | P13: 1. Augusto Pires*️⃣/Paulo Marcelo*️⃣
B14: 8º | C14: =G20 -> MARCUS KAUAN/EWERTON | F14: 7º | G14: =G19 -> GUILHERME/ENOQUE | K14: 2º | L14: JEAN/KAKÁ | M14: 560 | N14: 260 | O14: =SUM(M14:N14) -> 820 | P14: 2. Guilherme✅/Enoque✅
B15: RANKING 2025 | K15: 3º | L15: ANTÔNIO/LEONARDO | M15: 400 | N15: 0 | O15: =SUM(M15:N15) -> 400 | P15: 3. Marcus Kauã✅/Ewerton✅
B16: Colocação | C16: Dupla | D16: Pontuação | F16: Colocação | G16: Dupla | H16: Pontuação | K16: 4º | L16: DUUH/ÍTALO | M16: 220 | N16: 0 | O16: =SUM(M16:N16) -> 220 | P16: 4. Jean✅/Kaka✅
B17: 1º | C17: DUDU SANTOS/THAYUAN | D17: 740 + 740 = 1480 | F17: 5º | G17: PEDRO/MARCELLO | H17: 100 + 0 = 100 | K17: 5º | L17: AUGUSTO/MARCELLO | M17: 100 | N17: 0 | O17: =SUM(M17:N17) -> 100 | P17: 5. Duuh✅/Ítalo Lopes✅
B18: 2º | C18: JEAN/KAKÁ | D18: 560 + 260 = 820 | F18: 6º | G18: ADRIANO/MARCUS VINÍCIUS | H18: 0 | K18: 6º | L18: GUILHERME/ENOQUE | M18: 0 | N18: 0 | O18: =SUM(M18:N18) -> 0 | P18: 6. Leonardo✅/Antônio✅
B19: 3º | C19: ANTÔNIO/LEONARDO | D19: 400 + 0 = 400 | F19: 7º | G19: GUILHERME/ENOQUE | H19: 0 | K19: 7º | L19: MARCUS KAUAN/EWERTON | M19: 0 | N19: 0 | O19: =SUM(M19:N19) -> 0 | P19: 7. Dudu/Thayaun
B20: 4º | C20: DUUH/ÍTALO | D20: 220 + 0 = 220 | F20: 8º | G20: MARCUS KAUAN/EWERTON | H20: 0 | K20: 8º | L20: ADRIANO/MARCUS VINÍCIUS | M20: 0 | N20: 0 | O20: =SUM(M20:N20) -> 0 | P20: 8. Adriano/Marcus

Sheet TABELA
B2: CIRCUITO NCT VÔLEI DE PRAIA - 2025
B3: 5ª Etapa - Parque da Cidade
B4: INICIANTE MASCULINO
B5: 6 de dezembro de 2025 - sábado
B6: TABELA
B8: FASE DE GRUPOS
B9: Jogo | C9: Grupo | D9: Hora | E9: Quadra | F9: Rnk | G9: Equipe 1 | I9: 2º | J9: 3º | M9: 2º | N9: 3º | O9: UF | P9: Equipe 2
B10: 1 | C10: A | D10: 0.33333333 | G10: =GRUPOS!C11 -> DUDU SANTOS/THAYUAN | H10: 0 | K10: X | L10: W | P10: =GRUPOS!C14 -> MARCUS KAUAN/EWERTON
B11: 2 | C11: B | D11: 0.33333333 | G11: =GRUPOS!G11 -> JEAN/KAKÁ | H11: 21 | K11: X | L11: 11 | P11: =GRUPOS!G14 -> GUILHERME/ENOQUE
B12: 3 | C12: A | G12: =GRUPOS!C12 -> DUUH/ÍTALO | H12: 17 | K12: X | L12: 21 | P12: =GRUPOS!C13 -> PEDRO/MARCELLO
B13: 4 | C13: B | G13: =GRUPOS!G12 -> ANTÔNIO/LEONARDO | H13: 22 | K13: X | L13: 24 | P13: =GRUPOS!G13 -> ADRIANO/MARCUS VINÍCIUS
B14: 5 | C14: A | G14: =GRUPOS!C11 -> DUDU SANTOS/THAYUAN | H14: 0 | K14: X | L14: W | P14: =GRUPOS!C13 -> PEDRO/MARCELLO
B15: 6 | C15: B | G15: =GRUPOS!G11 -> JEAN/KAKÁ | H15: 21 | K15: X | L15: 19 | P15: =GRUPOS!G13 -> ADRIANO/MARCUS VINÍCIUS
B16: 7 | C16: A | G16: =GRUPOS!C12 -> DUUH/ÍTALO | H16: 21 | K16: X | L16: 19 | P16: =GRUPOS!C14 -> MARCUS KAUAN/EWERTON
B17: 8 | C17: B | G17: =GRUPOS!G12 -> ANTÔNIO/LEONARDO | H17: 21 | K17: X | L17: 7 | P17: =GRUPOS!G14 -> GUILHERME/ENOQUE
B18: 9 | C18: A | G18: =GRUPOS!C11 -> DUDU SANTOS/THAYUAN | H18: 0 | K18: X | L18: W | P18: =GRUPOS!C12 -> DUUH/ÍTALO
B19: 10 | C19: B | G19: =GRUPOS!G11 -> JEAN/KAKÁ | H19: 23 | K19: X | L19: 25 | P19: =GRUPOS!G12 -> ANTÔNIO/LEONARDO
B20: 11 | C20: A | G20: =GRUPOS!C13 -> PEDRO/MARCELLO | H20: 21 | K20: X | L20: 14 | P20: =GRUPOS!C14 -> MARCUS KAUAN/EWERTON
B21: 12 | C21: B | G21: =GRUPOS!G13 -> ADRIANO/MARCUS VINÍCIUS | H21: 21 | K21: X | L21: 7 | P21: =GRUPOS!G14 -> GUILHERME/ENOQUE
B23: QUARTAS-DE-FINAL
B24: 13 | G24: =AVERAGE!C34 -> DUUH/ÍTALO | H24: 12 | K24: X | L24: 21 | P24: =AVERAGE!C39 -> JEAN/KAKÁ
B25: 14 | G25: =AVERAGE!C38 -> ANTÔNIO/LEONARDO | H25: 21 | K25: X | L25: 13 | P25: =AVERAGE!C35 -> MARCUS KAUÂ/EWERTON
B27: SEMIFINAIS
B28: 15 | G28: =AVERAGE!C37 -> ADRIANO/MARCUS VINÍCIUS | H28: 21 | K28: X | L28: 16 | P28: JEAN/KAKÁ
B29: 16 | G29: =AVERAGE!C33 -> PEDRO/MARCELLO | H29: 15 | K29: X | L29: 21 | P29: ANTÔNIO/LEORNADO
B31: FINAL 1: disputa pelo 3º lugar
B32: 17 | G32: JEAN/KAKÁ | H32: 21 | K32: X | L32: 17 | P32: PEDRO/MARCELLO
B34: FINAL 2: disputa pelo 1º lugar
B35: 18 | G35: ADRIANO/MARCUS VINÍCIUS | H35: 2 | K35: X | L35: 0 | P35: ANTÔNIO/ LEONARDO

Sheet AVERAGE
B2: CIRCUITO NCT VÔLEI DE PRAIA - 2025
B3: 5ª Etapa - Parque da Cidade
B4: INICIANTE MASCULINO
B5: 6 de dezembro de 2025 - sábado
B6: AVERAGE
B10: CHAVE A
B12: =GRUPOS!C11 -> DUDU SANTOS/THAYUAN | C12: PRO | D12: CONTRA | F12: =GRUPOS!C12 -> DUUH/ÍTALO | G12: PRO | H12: CONTRA | J12: =GRUPOS!C13 -> PEDRO/MARCELLO | K12: PRO | L12: CONTRA | N12: =GRUPOS!C14 -> MARCUS KAUAN/EWERTON | O12: PRO | P12: CONTRA
B13: 1 | C13: =TABELA!H10 -> 0 | D13: =TABELA!L10 -> W | F13: 1 | G13: =TABELA!H12 -> 17 | H13: =TABELA!L12 -> 21 | J13: 1 | K13: =TABELA!L12 -> 21 | L13: =TABELA!H12 -> 17 | N13: 1 | O13: =TABELA!L10 -> W | P13: =TABELA!H10 -> 0
B14: 2 | C14: =TABELA!H14 -> 0 | D14: =TABELA!L14 -> W | F14: 2 | G14: =TABELA!H16 -> 21 | H14: =TABELA!L16 -> 19 | J14: 2 | K14: =TABELA!L14 -> W | L14: =TABELA!H14 -> 0 | N14: 2 | O14: =TABELA!L16 -> 19 | P14: =TABELA!H16 -> 21
B15: 3 | C15: =TABELA!H18 -> 0 | D15: =TABELA!L18 -> W | F15: 3 | G15: =TABELA!L18 -> W | H15: =TABELA!H18 -> 0 | J15: 3 | K15: =TABELA!H20 -> 21 | L15: =TABELA!L20 -> 14 | N15: 3 | O15: =TABELA!L20 -> 14 | P15: =TABELA!H20 -> 21
B16: TOTAL | C16: =SUM(C13:C15) -> 0 | D16: =SUM(D13:D15) -> 0 | F16: TOTAL | G16: =SUM(G13:G15) -> 38 | H16: =SUM(H13:H15) -> 40 | J16: TOTAL | K16: =SUM(K13:K15) -> 42 | L16: =SUM(L13:L15) -> 31 | N16: TOTAL | O16: =SUM(O13:O15) -> 33 | P16: =SUM(P13:P15) -> 42
B17: MEDIA | C17: 4º | D17: =C16/D16 -> #DIV/0! | F17: MEDIA | G17: 1º | H17: =G16/H16 -> 0.95 | J17: MEDIA | K17: 2º | L17: =K16/L16 -> 1.3548387 | N17: MEDIA | O17: 3º | P17: =O16/P16 -> 0.78571429
B21: CHAVE B
B23: =GRUPOS!G11 -> JEAN/KAKÁ | C23: PRO | D23: CONTRA | F23: =GRUPOS!G12 -> ANTÔNIO/LEONARDO | G23: PRO | H23: CONTRA | J23: =GRUPOS!G13 -> ADRIANO/MARCUS VINÍCIUS | K23: PRO | L23: CONTRA | N23: =GRUPOS!G14 -> GUILHERME/ENOQUE | O23: PRO | P23: CONTRA
B24: 1 | C24: =TABELA!H11 -> 21 | D24: =TABELA!L11 -> 11 | F24: 1 | G24: =TABELA!H13 -> 22 | H24: =TABELA!L13 -> 24 | J24: 1 | K24: =TABELA!L13 -> 24 | L24: =TABELA!H13 -> 22 | N24: 1 | O24: =TABELA!L11 -> 11 | P24: =TABELA!H11 -> 21
B25: 2 | C25: =TABELA!H15 -> 21 | D25: =TABELA!L15 -> 19 | F25: 2 | G25: =TABELA!H17 -> 21 | H25: =TABELA!L17 -> 7 | J25: 2 | K25: =TABELA!L15 -> 19 | L25: =TABELA!H15 -> 21 | N25: 2 | O25: =TABELA!L17 -> 7 | P25: =TABELA!H17 -> 21
B26: 3 | C26: =TABELA!H19 -> 23 | D26: =TABELA!L19 -> 25 | F26: 3 | G26: =TABELA!L19 -> 25 | H26: =TABELA!H19 -> 23 | J26: 3 | K26: =TABELA!H21 -> 21 | L26: =TABELA!L21 -> 7 | N26: 3 | O26: =TABELA!L21 -> 7 | P26: =TABELA!H21 -> 21
B27: TOTAL | C27: =SUM(C24:C26) -> 65 | D27: =SUM(D24:D26) -> 55 | F27: TOTAL | G27: =SUM(G24:G26) -> 68 | H27: =SUM(H24:H26) -> 54 | J27: TOTAL | K27: =SUM(K24:K26) -> 64 | L27: =SUM(L24:L26) -> 50 | N27: TOTAL | O27: =SUM(O24:O26) -> 25 | P27: =SUM(P24:P26) -> 63
B28: MEDIA | C28: 1º | D28: =C27/D27 -> 1.1818182 | F28: MEDIA | G28: 4º | H28: =G27/H27 -> 1.2592593 | J28: MEDIA | K28: 3º | L28: =K27/L27 -> 1.28 | N28: MEDIA | O28: 2º | P28: =O27/P27 -> 0.3968254
B31: CLASSIFICADOS
B32: POSIÇÃO | C32: DUPLA | J32: VITÓRIAS | K32: AVERAGE
B33: 1º A | C33: PEDRO/MARCELLO | J33: 3 | K33: 1.35489
B34: 2º A | C34: DUUH/ÍTALO | J34: 2 | K34: 0.95
B35: 3º A | C35: MARCUS KAUÂ/EWERTON | J35: 1 | K35: 0.7857
B36: 4º A | C36: 4º Colocado Grupo A | J36: 0
B37: 1º B | C37: ADRIANO/MARCUS VINÍCIUS | J37: 2 | K37: 1.28
B38: 2º B | C38: ANTÔNIO/LEONARDO | J38: 2 | K38: 1.259
B39: 3º B | C39: JEAN/KAKÁ | J39: 2 | K39: 1.1818
B40: 4º A | C40: 4º Colocado Grupo B | J40: 0 | K40: 0.39
