Workbook
Name FromArray_1: _xlfn.ANCHORARRAY(#REF!)
Name FromArray_1: _xlfn.ANCHORARRAY(#REF!)

Sheet RANKING 2025
B2: CIRCUITO NCT VÔLEI DE PRAIA - 2025
B3: Master 45+ Masculino
B4: RANKING
B5: Posição | C5: Atleta | D5: Nome completo | E5: Centro de | F5: UF | G5: 1ª Etapa | H5: 2ª Etapa | I5: 3ª Etapa | J5: 4ª Etapa | K5: 5ª Etapa | L5: Total
E6: Treinamento | G6: Arena Caffe | H6: Parque da Cidade | I6: Vamo Beach | J6: Arena 61 | K6: Parque da Cidade
B7: 1 | C7: FABIANO | D7: Fabiano de Oliveira Ananias | E7: CT Leander | F7: DF | G7: 160 | H7: 180 | I7: 160 | J7: 0 | K7: 200 | L7: =SUM(G7:K7) -> 700
B8: 2 | C8: SANDRO GRADICI | D8: Sandro Gradici | E8: Praia e Cerrado ASTCU | F8: RJ | G8: 180 | H8: 200 | I8: 0 | J8: 180 | K8: 120 | L8: =SUM(G8:K8) -> 680
B9: 3 | C9: JALEX | D9: Jorge Alexandre Costa | E9: Mundial do Guará | F9: DF | G9: 200 | H9: 160 | I9: 120 | J9: 180 | K9: 0 | L9: =SUM(G9:K9) -> 660
B10: 4 | C10: IVAN | D10: Ivan Fonseca Filho | E10: CT Leander | F10: DF | G10: 100 | H10: 140 | I10: 120 | J10: 140 | K10: 160 | L10: =SUM(G10:K10) -> 660
B11: 5 | C11: JEFF MISERA | D11: Jefferson Lourenço de Oliveira | E11: Metropolitana | F11: DF | G11: 120 | H11: 120 | I11: 120 | J11: 160 | K11: 120 | L11: =SUM(G11:K11) -> 640
C12: MARCO RAMOS | D12: Marco Antonio dos Santos Ramos | E12: CT Vôlei Brasília | F12: DF | G12: 120 | H12: 120 | I12: 120 | J12: 160 | K12: 120 | L12: =SUM(G12:K12) -> 640
B13: 6 | C13: CLÁUDIO | D13: Cláudio Torres de Oliveira | E13: Praia e Cerrado ASTCU | F13: DF | G13: 140 | H13: 120 | I13: 120 | J13: 120 | K13: 140 | L13: =SUM(G13:K13) -> 640
B14: 7 | C14: EURÍPEDES | D14: Euripedes Nunes Braga | E14: Fitvôlei Nação | F14: DF | G14: 120 | H14: 0 | I14: 200 | J14: 200 | K14: 100 | L14: =SUM(G14:K14) -> 620
B15: 8 | C15: GILSÃO | D15: Gilson Francisco dos Santos | E15: Metropolitana | F15: DF | G15: 120 | H15: 100 | I15: 200 | J15: 200 | K15: 0 | L15: =SUM(G15:K15) -> 620
B16: 8 | C16: LOBERA | D16: Welton Rabelo da Silva | E16: Praia e Cerrado ASTCU | F16: DF | G16: 180 | H16: 200 | I16: 120 | J16: 0 | K16: 120 | L16: =SUM(G16:K16) -> 620
B17: 9 | C17: CHARLLES | D17: Charlles Elias Sales Silva | E17: CT Ceilândia | F17: DF | G17: 120 | H17: 100 | I17: 180 | J17: 0 | K17: 180 | L17: =SUM(G17:K17) -> 580
B18: 10 | C18: LEANDRÃO | D18: Leandro Roberto de Lima Aoyama | E18: CT Leander | F18: DF | G18: 0 | H18: 180 | I18: 160 | J18: 0 | K18: 200 | L18: =SUM(G18:K18) -> 540
B19: 11 | C19: JEFFERSON | D19: Jefferson de Oliveira Melo | E19: CT Ceilândia/JK | F19: DF | G19: 200 | H19: 160 | I19: 120 | J19: 0 | K19: 0 | L19: =SUM(G19:K19) -> 480
B20: 12 | C20: DIVINO | D20: Divino Reis Pinto da Silva | E20: Metropolitana | F20: DF | G20: 100 | H20: 0 | I20: 120 | J20: 140 | K20: 100 | L20: =SUM(G20:K20) -> 460
B21: 13 | C21: BETO | D21: Jose Roberto de Abreu Carretero Filho | E21: JR Integração | F21: DF | G21: 120 | H21: 120 | I21: 100 | J21: 0 | K21: 120 | L21: =SUM(G21:K21) -> 460
B22: 14 | C22: RENATO | D22: Renato Ferreira dos Santos | E22: Arena Caffe | F22: DF | G22: 0 | H22: 100 | I22: 180 | J22: 0 | K22: 140 | L22: =SUM(G22:K22) -> 420
B23: 15 | C23: JUCA | D23: José Joaquim da Silva Júnior | E23: Iate Clube | F23: DF | G23: 100 | H23: 0 | I23: 120 | J23: 120 | K23: 0 | L23: =SUM(G23:K23) -> 340
C24: JUVENAL | D24: Juvenal de Souza Andrade | E24: Arena Caffe | F24: DF | G24: 100 | H24: 120 | I24: 0 | J24: 0 | K24: 120 | L24: =SUM(G24:K24) -> 340
C25: PRESIDENTE | D25: George Adriano Teles Rodrigues | E25: Mundial do Guará | F25: DF | G25: 120 | H25: 0 | I25: 100 | J25: 0 | K25: 120 | L25: =SUM(G25:K25) -> 340
B26: 16 | C26: CONDOR | D26: Robson Ulisses | E26: Arena Caffe | F26: DF | G26: 0 | H26: 100 | I26: 0 | J26: 120 | K26: 100 | L26: =SUM(G26:K26) -> 320
C27: GRANDE | D27: Euzélio Guimarães | E27: Arena Caffe | F27: DF | G27: 100 | H27: 0 | I27: 0 | J27: 120 | K27: 100 | L27: =SUM(G27:K27) -> 320
B28: 17 | C28: MÁRIO | D28: Mário Florêncio Silva | E28: CT Ceilândia | F28: DF | G28: 120 | H28: 0 | I28: 0 | J28: 0 | K28: 180 | L28: =SUM(G28:K28) -> 300
B29: 18 | C29: PAULO CEARÁ | D29: Paulo Itaicy Marques Rodrigues | E29: NCT Vôlei de Praia | F29: DF | G29: 0 | H29: 100 | I29: 100 | J29: 0 | K29: 100 | L29: =SUM(G29:K29) -> 300
B30: 19 | C30: DENNY | D30: Denny Calvis Lopes | E30: Não tem | F30: DF | G30: 160 | H30: 120 | I30: 0 | J30: 0 | K30: 0 | L30: =SUM(G30:K30) -> 280
B31: 20 | C31: SANDRO MARINS | D31: Alessandro Marins de Oliveira | E31: CT Leander | F31: DF | G31: 0 | H31: 0 | I31: 100 | J31: 0 | K31: 160 | L31: =SUM(G31:K31) -> 260
B32: 21 | C32: ALAN | D32: Alan Carlos Brandão | E32: Luziânia | F32: GO | G32: 0 | H32: 0 | I32: 100 | J32: 120 | K32: 0 | L32: =SUM(G32:K32) -> 220
C33: MARCELO | D33: Marcelo de Brito Gaspareto | E33: Fitvôlei Nação | F33: DF | G33: 100 | H33: 0 | I33: 0 | J33: 120 | K33: 0 | L33: =SUM(G33:K33) -> 220
C34: MILER | D34: Milciades Leal de Souza | E34: Arena Caffe | F34: DF | G34: 100 | H34: 0 | I34: 0 | J34: 120 | K34: 0 | L34: =SUM(G34:K34) -> 220
C35: W. LUCAS | D35: Wander Lucas Val da Silva | E35: NCT Vôlei de Praia | F35: DF | G35: 100 | H35: 120 | I35: 0 | J35: 0 | K35: 0 | L35: =SUM(G35:K35) -> 220
B36: 22 | C36: CÉSAR | D36: César Augusto Tavares Chagas | E36: Ninho da Corija | F36: GO | G36: 100 | H36: 100 | I36: 0 | J36: 0 | K36: 0 | L36: =SUM(G36:K36) -> 200
C37: DIOGO | D37: Diogo Tadamitsu Takahashi | E37: Ninho da Corija | F37: GO | G37: 100 | H37: 100 | I37: 0 | J37: 0 | K37: 0 | L37: =SUM(G37:K37) -> 200
C38: EDUARDO | D38: Eduardo Lopes Franco | E38: CT Leander | F38: DF | G38: 100 | H38: 0 | I38: 0 | J38: 0 | K38: 100 | L38: =SUM(G38:K38) -> 200
C39: WASHINGTON | D39: Washington Furtado Cardoso | E39: NCT Vôlei de Praia | F39: DF | G39: 0 | H39: 100 | I39: 100 | J39: 0 | K39: 0 | L39: =SUM(G39:K39) -> 200
B40: 23 | C40: CARLÃO | D40: Carlos Augusto da Silva | E40: CT Lucas Fortuna | F40: GO | G40: 0 | H40: 140 | I40: 0 | J40: 0 | K40: 0 | L40: =SUM(G40:K40) -> 140
C41: MAURO | D41: Mauro Misquito | E41: São Conrado | F41: RJ | G41: 140 | H41: 0 | I41: 0 | J41: 0 | K41: 0 | L41: =SUM(G41:K41) -> 140
...

Sheet REGULAMENTO
B2: CIRCUITO NCT VÔLEI DE PRAIA - 2025
B4: REGULAMENTO
B6: 5ª Etapa | D6: MASTER 45+ MASCULINO | H6: 07/12/2025
B7: Parque da Cidade | H7: domingo
B9: item | C9: Título | D9: Descrição | H9: Observação
B10: 1 | C10: Ranking de entrada | D10: Ranking da temporada 2025. Nos casos de empate, prevalecerá a equipe que tiver a maior quantidade de melhores posições. P. ex.: o empate em pontos entre duplas será resolvido a favor da dupla que tem o maior número de 1º lugares, 2º, etc, e assim sucessivamente. Permancendo o empate, haverá sorteio.
B11: 2 | C11: Distribuição dos grupos | D11: Modelo de serpentina seguindo ranking 2025.
B12: 3 | C12: Quantidade de duplas | D12: 12 duplas (24 atletas).
B13: 4 | C13: Quantidade de jogos | D13: 26 partidas.
B14: 5 | C14: Quantidade de sets* | D14: 1 Set de 21 pontos. | H14: *Exceto a final 2.
B15: 6 | C15: Sistema de disputa da 1ª fase | D15: Todos contra todos no grupo. | H15: 3 jogos por equipe.
B16: 7 | C16: Critérios de desempate para definição de posições no grupo | D16: 1º - nº de vitórias.
D17: 2º - ponto average.
D18: 3º - confronto direto.
D19: 4º - sorteio.
B20: 8 | C20: Classificação no grupo | D20: Classificam-se os dois primeiros colocados de cada grupo e os dois melhores terceiros colocados nos três grupos.
C21: Classificação para quartas-de-final | D21: Classificação geral de 1º a 8º lugares, INDEPENDENTE DA POSIÇÃO DE CLASSIFICAÇÃO NO GRUPO, observando os critérios do item 7.
B22: 9 | C22: Distribuição de confrontos nas quartas-de-final | D22: Cruzamentos: (A: 1º X 8º) versus (B: 4º X 5º) / (C: 2º X 7º) versus (D: 3º X 6º).
B23: 10 | C23: Semifinais | D23: Cruzamentos: (A X B) e (C X D).
B24: 11 | C24: Final 1 (disputa pelo 3º lugar) | D24: Jogo entre os perdedores das semifinais: 1 Set de 21 pontos.
B25: 12 | C25: Final 2: (disputa pelo 1º lugar) | D25: Jogo entre os vencedores das semifinais: 2 sets de 21 pontos e set desempate de 15 pontos.
B26: 13 | C26: Pontuação em Wx0 | D26: As partidas resolvidas pela não apresentação de uma dupla resultará na vitória da dupla que se apresentou, contudo, não haverá saldo de pontos para nenhuma das duplas envolvidas. No caso de duplo W x 0, as duas duplas serão consideradas derrotadas e, consequentemente, sem saldo de pontos.
B27: 14 | C27: Pontuação em partida abandonada por desistência | D27: As partidas em que uma dupla desistir de continuar a partida, terá o placar de 21 (ou diferença de 2 pontos) para a equipe que não desistiu. A dupla que desistiu permanece com a pontuação do momento da desistência.
B28: 15 | C28: Pontuação no Ranking | D28: A distribuição de pontos por atleta ao final de cada etapa se dará da seguinte forma:
D29: 1º lugar: 200 / 2º lugar: 180 / 3º lugar: 160 / 4º lugar: 140 / 5º lugar: 120 / 9º lugar: 100.
B30: 16 | C30: Penalidades | D30: A atleta que agir com desrespeito e violência em relação à arbitragem, adversários, parceiro e qualquer pessoa presente, poderá ser suspenso ou banido do Circuito NCT por deliberação da Comissão Organizadora.
B31: 17 | C31: Suspensão de partidas | D31: As partidas que precisarem ser suspensas por motivos de mau tempo, falta de iluminação e assemelhados, retornará com o placar da interrupção, caso isso ocorra em até 4 horas. Após isso, a partida recomeçará com o placar de 0x0.
B32: 18 | C32: Uniformização | D32: Camiseta oficial do Circuito NCT Vôlei de Praia 2025. | H32: Obrigatória.
D33: Bermudas da mesma cor. | H33: Preferencialmente.
B34: 19 | C34: Horário de início | D34: 9h, em DUAS quadras.
B35: 20 | C35: Local da competição | D35: Parque da Cidade Sarah Kubitschek (próximo à ADM) - Localização compartilhada no grupo de whatsapp

Sheet GRUPOS
B2: CIRCUITO NCT VÔLEI DE PRAIA - 2025
B3: 5ª Etapa - Parque da Cidade
B4: Master 45+ Masculino
B5: 7 de dezembro de 2025 - domingo
B6: GRUPOS
B7: Distribuição pelo ranking no modo serpentina
B9: GRUPO A | F9: GRUPO B | J9: GRUPO C
B10: RK | C10: DUPLA | D10: CÓD | F10: RK | G10: DUPLA | H10: CÓD | J10: RK | K10: DUPLA | L10: CÓD
B11: 1º | C11: =C18 -> LOBERA/SANDRO GRADICI | D11: A1 | F11: 2º | G11: =C19 -> MARCO RAMOS/JEFF MISERA | H11: B1 | J11: 3º | K11: =C20 -> FABIANO/LEANDRÃO | L11: C1
B12: 6º | C12: =C23 -> BETO/PRESIDENTE | D12: A2 | F12: 5º | G12: =C22 -> IVAN/SANDRO MARINS | H12: B2 | J12: 4º | K12: =C21 -> CLÁUDIO/RENATO | L12: C2
B13: 7º | C13: =C24 -> EURÍPEDES/HUMBERTO | D13: A3 | F13: 8º | G13: =C25 -> CHARLLES/MÁRIO | H13: B3 | J13: 9º | K13: =C26 -> CONDOR/GRANDE | L13: C3
B14: 12º | C14: =C29 -> JUVENAL/ENOCH | D14: A4 | F14: 11º | G14: =C28 -> PAULO CEARÁ/EDUARDO | H14: B4 | J14: 10º | K14: =C27 -> DIVINO/JÚNIOR SAGRADO | L14: C4
B16: RANKING 2025 | O16: RANKING DE ENTRADA (DUPLAS) - MASTER 45+
B17: RK | C17: Dupla | I17: PONTUAÇÃO | L17: CÓD | O17: INSCRIÇÕES | Q17: AT 1 | R17: AT 2 | S17: TOTAL
B18: 1º | C18: LOBERA/SANDRO GRADICI | I18: 560 + 500 = 1060 | L18: A1 | O18: 1º | P18: LOBERA/SANDRO GRADICI | Q18: 560 | R18: 500 | S18: =SUM(Q18:R18) -> 1060 | T18: 1. Eurípedes✅/Humberto✅
B19: 2º | C19: MARCO RAMOS/JEFF MISERA | I19: 520 + 520 = 1040 | L19: B1 | O19: 2º | P19: MARCO RAMOS/JEFF MISERA | Q19: 520 | R19: 520 | S19: =SUM(Q19:R19) -> 1040 | T19: 2. Júnior✅/Divino✅
B20: 3º | C20: FABIANO/LEANDRÃO | I20: 500 + 340 = 840 | L20: C1 | O20: 3º | P20: FABIANO/LEANDRÃO | Q20: 500 | R20: 340 | S20: =SUM(Q20:R20) -> 840 | T20: 3. Ivan✅/Sandro Marins✅
B21: 4º | C21: CLÁUDIO/RENATO | I21: 500 + 280 = 780 | L21: C2 | O21: 4º | P21: CLÁUDIO/RENATO | Q21: 500 | R21: 280 | S21: =SUM(Q21:R21) -> 780 | T21: 4. Condor✅/Grande✅
B22: 5º | C22: IVAN/SANDRO MARINS | I22: 500 + 100 = 600 | L22: B2 | O22: 5º | P22: IVAN/SANDRO MARINS | Q22: 500 | R22: 100 | S22: =SUM(Q22:R22) -> 600 | T22: 5. Cláudio✅/Renatinho✅
B23: 6º | C23: BETO/PRESIDENTE | I23: 340 + 220 = 560 | L23: A2 | O23: 6º | P23: BETO/PRESIDENTE | Q23: 340 | R23: 220 | S23: =SUM(Q23:R23) -> 560 | T23: 6. Paulo Ceará✅/Eduardo Titânio✅
B24: 7º | C24: EURÍPEDES/HUMBERTO | I24: 520 + 0 = 520 | L24: A3 | O24: 7º | P24: EURÍPEDES/HUMBERTO | Q24: 520 | R24: 0 | S24: =SUM(Q24:R24) -> 520 | T24: 7. Marco Ramos✅/Jeff Misera✅
B25: 8º | C25: CHARLLES/MÁRIO | I25: 400 + 120 = 520 | L25: B3 | O25: 8º | P25: CHARLLES/MÁRIO | Q25: 400 | R25: 120 | S25: =SUM(Q25:R25) -> 520 | T25: 8. Lobera✅/Sandro Gradici✅
B26: 9º | C26: CONDOR/GRANDE | I26: 220 + 220 = 440 | L26: C3 | O26: 9º | P26: CONDOR/GRANDE | Q26: 220 | R26: 220 | S26: =SUM(Q26:R26) -> 440 | T26: 9. Enoch✅/Juvenal✅
B27: 10º | C27: DIVINO/JÚNIOR SAGRADO | I27: 360 + 0 = 360 | L27: C4 | O27: 10º | P27: DIVINO/JÚNIOR SAGRADO | Q27: 360 | R27: 0 | S27: =SUM(Q27:R27) -> 360 | T27: 10. Beto✅/Presidente✅
B28: 11º | C28: PAULO CEARÁ/EDUARDO | I28: 200 + 100 = 300 | L28: B4 | O28: 11º | P28: PAULO CEARÁ/EDUARDO | Q28: 200 | R28: 100 | S28: =SUM(Q28:R28) -> 300 | T28: 11. Fabiano✅/Leandrão✅
B29: 12º | C29: JUVENAL/ENOCH | I29: 220 + 0 = 220 | L29: A4 | O29: 12º | P29: JUVENAL/ENOCH | Q29: 220 | R29: 0 | S29: =SUM(Q29:R29) -> 220 | T29: 12. Mário✅/Charlles✅

Sheet TABELA
B2: CIRCUITO NCT VÔLEI DE PRAIA - 2025
B3: 5ª Etapa - Parque da Cidade
B4: Master 45+ Masculino
B5: 7 de dezembro de 2025 - domingo
B6: TABELA
B8: Fase de grupos
B9: Jogo | C9: Grupo | D9: Hora | E9: Quadra | F9: Código | G9: Equipe 1 | K9: Equipe 2 | L9: Código
B10: 1 | C10: A | D10: 0.375 | F10: A1 | G10: =GRUPOS!C11 -> LOBERA/SANDRO GRADICI | H10: 17 | I10: X | J10: 21 | K10: =GRUPOS!C14 -> JUVENAL/ENOCH | L10: A4
B11: 2 | C11: B | D11: 0.375 | F11: B1 | G11: =GRUPOS!G11 -> MARCO RAMOS/JEFF MISERA | H11: 21 | I11: X | J11: 16 | K11: =GRUPOS!G14 -> PAULO CEARÁ/EDUARDO | L11: B4
B12: 3 | C12: C | F12: C1 | G12: =GRUPOS!K11 -> FABIANO/LEANDRÃO | H12: 21 | I12: X | J12: 19 | K12: =GRUPOS!K14 -> DIVINO/JÚNIOR SAGRADO | L12: C4
B13: 4 | C13: A | F13: A2 | G13: =GRUPOS!C12 -> BETO/PRESIDENTE | H13: 21 | I13: X | J13: 11 | K13: =GRUPOS!C13 -> EURÍPEDES/HUMBERTO | L13: A3
B14: 5 | C14: B | F14: B2 | G14: =GRUPOS!G12 -> IVAN/SANDRO MARINS | H14: 21 | I14: X | J14: 16 | K14: =GRUPOS!G13 -> CHARLLES/MÁRIO | L14: B3
B15: 6 | C15: C | F15: C2 | G15: =GRUPOS!K12 -> CLÁUDIO/RENATO | H15: 21 | I15: X | J15: 5 | K15: =GRUPOS!K13 -> CONDOR/GRANDE | L15: C3
B16: 7 | C16: A | F16: A1 | G16: =GRUPOS!C11 -> LOBERA/SANDRO GRADICI | H16: 12 | I16: X | J16: 21 | K16: =GRUPOS!C13 -> EURÍPEDES/HUMBERTO | L16: A3
B17: 8 | C17: B | F17: B1 | G17: =GRUPOS!G11 -> MARCO RAMOS/JEFF MISERA | H17: 21 | I17: X | J17: 18 | K17: =GRUPOS!G13 -> CHARLLES/MÁRIO | L17: B3
B18: 9 | C18: C | F18: C1 | G18: =GRUPOS!K11 -> FABIANO/LEANDRÃO | H18: 21 | I18: X | J18: 18 | K18: =GRUPOS!K13 -> CONDOR/GRANDE | L18: C3
B19: 10 | C19: A | F19: A2 | G19: =GRUPOS!C12 -> BETO/PRESIDENTE | H19: 14 | I19: X | J19: 21 | K19: =GRUPOS!C14 -> JUVENAL/ENOCH | L19: A4
B20: 11 | C20: B | F20: B2 | G20: =GRUPOS!G12 -> IVAN/SANDRO MARINS | H20: 21 | I20: X | J20: 17 | K20: =GRUPOS!G14 -> PAULO CEARÁ/EDUARDO | L20: B4
B21: 12 | C21: C | D21: : | F21: C2 | G21: =GRUPOS!K12 -> CLÁUDIO/RENATO | H21: 21 | I21: X | J21: 18 | K21: =GRUPOS!K14 -> DIVINO/JÚNIOR SAGRADO | L21: C4
B22: 13 | C22: A | F22: A1 | G22: =GRUPOS!C11 -> LOBERA/SANDRO GRADICI | H22: 21 | I22: X | J22: 16 | K22: =GRUPOS!C12 -> BETO/PRESIDENTE | L22: A2
B23: 14 | C23: B | F23: B1 | G23: =GRUPOS!G11 -> MARCO RAMOS/JEFF MISERA | H23: 13 | I23: X | J23: 21 | K23: =GRUPOS!G12 -> IVAN/SANDRO MARINS | L23: B2
B24: 15 | C24: C | F24: C1 | G24: =GRUPOS!K11 -> FABIANO/LEANDRÃO | H24: 22 | I24: X | J24: 20 | K24: =GRUPOS!K12 -> CLÁUDIO/RENATO | L24: C2
B25: 16 | C25: A | F25: A3 | G25: =GRUPOS!C13 -> EURÍPEDES/HUMBERTO | H25: 12 | I25: X | J25: 21 | K25: =GRUPOS!C14 -> JUVENAL/ENOCH | L25: A4
B26: 17 | C26: B | F26: B3 | G26: =GRUPOS!G13 -> CHARLLES/MÁRIO | H26: W | I26: X | J26: 0 | K26: =GRUPOS!G14 -> PAULO CEARÁ/EDUARDO | L26: B4
B27: 18 | C27: C | F27: C3 | G27: =GRUPOS!K13 -> CONDOR/GRANDE | H27: 21 | I27: X | J27: 14 | K27: =GRUPOS!K14 -> DIVINO/JÚNIOR SAGRADO | L27: C4
B30: 19 | C30: QF | F30: 1º | G30: ='AVERAGE '!C45 -> JUVENAL/ENOCH | H30: 15 | I30: X | J30: 21 | K30: ='AVERAGE '!C52 -> CHARLLES/MÁRIO | L30: 8º
B31: 20 | C31: QF | F31: 4º | G31: ='AVERAGE '!C48 -> CLÁUDIO/RENATO | H31: 21 | I31: X | J31: 18 | K31: ='AVERAGE '!C49 -> MARCO RAMOS/JEFF MISERA | L31: 5º
B32: 21 | C32: QF | F32: 2º | G32: ='AVERAGE '!C46 -> IVAN/SANDRO MARINS | H32: 21 | I32: X | J32: 18 | K32: ='AVERAGE '!C51 -> LOBERA/SANDRO GRADICI | L32: 7º
B33: 22 | C33: QF | F33: 3º | G33: ='AVERAGE '!C47 -> FABIANO/LEANDRÃO | H33: 21 | I33: X | J33: 12 | K33: ='AVERAGE '!C50 -> BETO/PRESIDENTE | L33: 6º
B35: Semifinais
B36: 23 | C36: SF | F36: V J 19 | G36: CHARLLES/MÁRIO | H36: 21 | I36: X | J36: 18 | K36: CLÁUDIO/RENATO | L36: V J 20
B37: 24 | C37: SF | F37: V J 21 | G37: IVAN/SANDRO MARINS | H37: 15 | I37: X | J37: 21 | K37: FABIANO/LEANDRÃO | L37: V J 22
B39: Final 1: disputa pelo 3º lugar
B40: 25 | C40: F1 | F40: P J 23 | G40: IVAN/SANDRO MARINS | H40: 15 | I40: X | J40: 21 | K40: CLÁUDIO/RENATO | L40: P J 24
B42: Final 2: disputa pelo 1º lugar
B43: 26 | C43: F2 | F43: V J 23 | G43: CHARLLES/MÁRIO | H43: 1 | I43: X | J43: 2 | K43: FABIANO/LEANDRÃO | L43: V J 24

Sheet AVERAGE 
B2: CIRCUITO NCT VÔLEI DE PRAIA - 2025
B3: 5ª Etapa - Parque da Cidade
B4: Master 45+ Masculino
B5: 7 de dezembro de 2025 - domingo
B6: AVERAGE
B10: GRUPO A
B12: =GRUPOS!C11 -> LOBERA/SANDRO GRADICI | C12: PRO | D12: CONTRA | F12: =GRUPOS!C12 -> BETO/PRESIDENTE | G12: PRO | H12: CONTRA | J12: =GRUPOS!C13 -> EURÍPEDES/HUMBERTO | K12: PRO | L12: CONTRA | N12: =GRUPOS!C14 -> JUVENAL/ENOCH | O12: PRO | P12: CONTRA
B13: 1 | C13: =TABELA!H10 -> 17 | D13: =TABELA!J10 -> 21 | F13: 1 | G13: =TABELA!H13 -> 21 | H13: =TABELA!J13 -> 11 | J13: 1 | K13: =TABELA!J13 -> 11 | L13: =TABELA!H13 -> 21 | N13: 1 | O13: =TABELA!J10 -> 21 | P13: =TABELA!H10 -> 17
B14: 2 | C14: =TABELA!H16 -> 12 | D14: =TABELA!J16 -> 21 | F14: 2 | G14: =TABELA!H19 -> 14 | H14: =TABELA!J19 -> 21 | J14: 2 | K14: =TABELA!J16 -> 21 | L14: =TABELA!H16 -> 12 | N14: 2 | O14: =TABELA!J19 -> 21 | P14: =TABELA!H19 -> 14
B15: 3 | C15: =TABELA!H22 -> 21 | D15: =TABELA!J22 -> 16 | F15: 3 | G15: =TABELA!J22 -> 16 | H15: =TABELA!H22 -> 21 | J15: 3 | K15: =TABELA!H25 -> 12 | L15: =TABELA!J25 -> 21 | N15: 3 | O15: =TABELA!J25 -> 21 | P15: =TABELA!H25 -> 12
B16: TOTAL | C16: =SUM(C13:C15) -> 50 | D16: =SUM(D13:D15) -> 58 | F16: TOTAL | G16: =SUM(G13:G15) -> 51 | H16: =SUM(H13:H15) -> 53 | J16: TOTAL | K16: =SUM(K13:K15) -> 44 | L16: =SUM(L13:L15) -> 54 | N16: TOTAL | O16: =SUM(O13:O15) -> 63 | P16: =SUM(P13:P15) -> 43
B17: MEDIA | C17: 2 | D17: =C16/D16 -> 0.86206897 | F17: MEDIA | G17: 1 | H17: =G16/H16 -> 0.96226415 | J17: MEDIA | L17: =K16/L16 -> 0.81481481 | N17: MEDIA | O17: 3 | P17: =O16/P16 -> 1.4651163
B21: GRUPO B
B23: =GRUPOS!G11 -> MARCO RAMOS/JEFF MISERA | C23: PRO | D23: CONTRA | F23: =GRUPOS!G12 -> IVAN/SANDRO MARINS | G23: PRO | H23: CONTRA | J23: =GRUPOS!G13 -> CHARLLES/MÁRIO | K23: PRO | L23: CONTRA | N23: =GRUPOS!G14 -> PAULO CEARÁ/EDUARDO | O23: PRO | P23: CONTRA
B24: 1 | C24: =TABELA!H11 -> 21 | D24: =TABELA!J11 -> 16 | F24: 1 | G24: =TABELA!H14 -> 21 | H24: =TABELA!J14 -> 16 | J24: 1 | K24: =TABELA!J14 -> 16 | L24: =TABELA!H14 -> 21 | N24: 1 | O24: =TABELA!J11 -> 16 | P24: =TABELA!H11 -> 21
B25: 2 | C25: =TABELA!H17 -> 21 | D25: =TABELA!J17 -> 18 | F25: 2 | G25: =TABELA!H20 -> 21 | H25: =TABELA!J20 -> 17 | J25: 2 | K25: =TABELA!J17 -> 18 | L25: =TABELA!H17 -> 21 | N25: 2 | O25: =TABELA!J20 -> 17 | P25: =TABELA!H20 -> 21
B26: 3 | C26: =TABELA!H23 -> 13 | D26: =TABELA!J23 -> 21 | F26: 3 | G26: =TABELA!J23 -> 21 | H26: =TABELA!H23 -> 13 | J26: 3 | K26: =TABELA!H26 -> W | L26: =TABELA!J26 -> 0 | N26: 3 | O26: =TABELA!J26 -> 0 | P26: =TABELA!H26 -> W
B27: TOTAL | C27: =SUM(C24:C26) -> 55 | D27: =SUM(D24:D26) -> 55 | F27: TOTAL | G27: =SUM(G24:G26) -> 63 | H27: =SUM(H24:H26) -> 46 | J27: TOTAL | K27: =SUM(K24:K26) -> 34 | L27: =SUM(L24:L26) -> 42 | N27: TOTAL | O27: =SUM(O24:O26) -> 33 | P27: =SUM(P24:P26) -> 42
B28: MEDIA | D28: =C27/D27 -> 1 | F28: MEDIA | H28: =G27/H27 -> 1.3695652 | J28: MEDIA | L28: =K27/L27 -> 0.80952381 | N28: MEDIA | P28: =O27/P27 -> 0.78571429
B32: GRUPO C
B34: =GRUPOS!K11 -> FABIANO/LEANDRÃO | C34: PRO | D34: CONTRA | F34: =GRUPOS!K12 -> CLÁUDIO/RENATO | G34: PRO | H34: CONTRA | J34: =GRUPOS!K13 -> CONDOR/GRANDE | K34: PRO | L34: CONTRA | N34: =GRUPOS!K14 -> DIVINO/JÚNIOR SAGRADO | O34: PRO | P34: CONTRA
B35: 1 | C35: =TABELA!H12 -> 21 | D35: =TABELA!J12 -> 19 | F35: 1 | G35: =TABELA!H15 -> 21 | H35: =TABELA!J15 -> 5 | J35: 1 | K35: =TABELA!J15 -> 5 | L35: =TABELA!H15 -> 21 | N35: 1 | O35: =TABELA!J12 -> 19 | P35: =TABELA!H12 -> 21
B36: 2 | C36: =TABELA!H18 -> 21 | D36: =TABELA!J18 -> 18 | F36: 2 | G36: =TABELA!H21 -> 21 | H36: =TABELA!J21 -> 18 | J36: 2 | K36: =TABELA!J18 -> 18 | L36: =TABELA!H18 -> 21 | N36: 2 | O36: =TABELA!J21 -> 18 | P36: =TABELA!H21 -> 21
B37: 3 | C37: =TABELA!H24 -> 22 | D37: =TABELA!J24 -> 20 | F37: 3 | G37: =TABELA!J24 -> 20 | H37: =TABELA!H24 -> 22 | J37: 3 | K37: =TABELA!H27 -> 21 | L37: =TABELA!J27 -> 14 | N37: 3 | O37: =TABELA!J27 -> 14 | P37: =TABELA!H27 -> 21
B38: TOTAL | C38: =SUM(C35:C37) -> 64 | D38: =SUM(D35:D37) -> 57 | F38: TOTAL | G38: =SUM(G35:G37) -> 62 | H38: =SUM(H35:H37) -> 45 | J38: TOTAL | K38: =SUM(K35:K37) -> 44 | L38: =SUM(L35:L37) -> 56 | N38: TOTAL | O38: =SUM(O35:O37) -> 51 | P38: =SUM(P35:P37) -> 63
B39: MEDIA | D39: =C38/D38 -> 1.122807 | F39: MEDIA | H39: =G38/H38 -> 1.3777778 | J39: MEDIA | L39: =K38/L38 -> 0.78571429 | N39: MEDIA | P39: =O38/P38 -> 0.80952381
B43: CLASSIFICADOS
B44: POSIÇÃO | C44: DUPLA | K44: VITÓRIAS | M44: CLASSIFICAÇÃO NO GRUPO | O44: AVERAGE
B45: 1º | C45: JUVENAL/ENOCH | K45: 3 | M45: 1 | O45: 1.4651163
B46: 2º | C46: IVAN/SANDRO MARINS | K46: 3 | M46: 1 | O46: 1.3695652
B47: 3º | C47: FABIANO/LEANDRÃO | K47: 3 | M47: 1 | O47: 1.122807
B48: 4º | C48: CLÁUDIO/RENATO | K48: 2 | M48: 2 | O48: 1.3777778
B49: 5º | C49: MARCO RAMOS/JEFF MISERA | K49: 2 | M49: 2
B50: 6º | C50: BETO/PRESIDENTE | K50: 2 | M50: 2 | O50: 0.96226415
B51: 7º | C51: LOBERA/SANDRO GRADICI | K51: 1 | M51: 3 | O51: 0.86206897
B52: 8º | C52: CHARLLES/MÁRIO | K52: 1 | M52: 3 | O52: 0.80952381
F55: RASCUNHO | I55: DUPLA | K55: VITÓRIAS | M55: CLASSIFICAÇÃO NO GRUPO | O55: AVERAGE
