Workbook
Name FromArray_1: _xlfn.ANCHORARRAY(#REF!)

Sheet GRUPOS
B2: Circuito NCT Vôlei de Praia 2026 - 1ª Etapa - Arena Caffe
B3: GRUPOS - Aberto Masculino
B4: Distribuição pelo ranking no modo serpentina
B6: GRUPO A | F6: GRUPO B | J6: GRUPO C | N6: GRUPO D
B7: RK | C7: DUPLA | D7: CÓD | F7: RK | G7: DUPLA | H7: CÓD | J7: RK | K7: DUPLA | L7: CÓD | N7: RK | O7: DUPLA | P7: CÓD
B8: 1º | C8: =C14 -> Ranking 1 | D8: A1 | F8: 2º | G8: =C15 -> Ranking 2 | H8: B1 | J8: 3º | K8: =C16 -> Ranking 3 | L8: C1 | N8: 4º | O8: =C17 -> Ranking 4 | P8: D1
B9: 8º | C9: =C21 -> Ranking 8 | D9: A2 | F9: 7º | G9: =C20 -> Ranking 7 | H9: B2 | J9: 6º | K9: =C19 -> Ranking 6 | L9: C2 | N9: 5º | O9: =C18 -> Ranking 5 | P9: D2
B10: 9º | C10: =K14 -> Ranking 9 | D10: A3 | F10: 10º | G10: =K15 -> Ranking 10 | H10: B3 | J10: 11º | K10: =K16 -> Ranking 11 | L10: C3 | N10: 12º | O10: =K17 -> Ranking 12 | P10: D3
B11: 16º | C11: =K21 -> Ranking 16 | D11: A4 | F11: 15º | G11: =K20 -> Ranking 15 | H11: B4 | J11: 14º | K11: =K19 -> Ranking 14 | L11: C4 | N11: 13º | O11: =K18 -> Ranking 13 | P11: D4
B12: RANKING 2025
B13: RK | C13: Dupla | H13: CÓD | J13: RK | K13: Dupla | P13: CÓD
B14: 1º | C14: Ranking 1 | F14: Sorteio | H14: A1 | J14: 9º | K14: Ranking 9 | N14: Sorteio | P14: A3
B15: 2º | C15: Ranking 2 | F15: Sorteio | H15: B1 | J15: 10º | K15: Ranking 10 | N15: Sorteio | P15: B3
B16: 3º | C16: Ranking 3 | F16: Sorteio | H16: C1 | J16: 11º | K16: Ranking 11 | N16: Sorteio | P16: C3
B17: 4º | C17: Ranking 4 | F17: Sorteio | H17: D1 | J17: 12º | K17: Ranking 12 | N17: Sorteio | P17: D3
B18: 5º | C18: Ranking 5 | F18: Sorteio | H18: D2 | J18: 13º | K18: Ranking 13 | N18: Sorteio | P18: D4
B19: 6º | C19: Ranking 6 | F19: Sorteio | H19: C2 | J19: 14º | K19: Ranking 14 | N19: Sorteio | P19: C4
B20: 7º | C20: Ranking 7 | F20: Sorteio | H20: B2 | J20: 15º | K20: Ranking 15 | N20: Sorteio | P20: B4
B21: 8º | C21: Ranking 8 | F21: Sorteio | H21: A2 | J21: 16º | K21: Ranking 16 | N21: Sorteio | P21: A4

Sheet TABELA_AVERAGE
B2: Circuito NCT Vôlei de Praia 2026 - 1ª Etapa - Arena Caffe | AG2: AVERAGE
B3: Aberto Masculino | AG3: GRUPO A
B4: Tabela | P4: Average | AG4: =GRUPOS!C14 -> Ranking 1 | AH4: PRO | AI4: CONTRA | AK4: =GRUPOS!Q9 -> 0 | AL4: PRO | AM4: CONTRA | AO4: =GRUPOS!Q10 -> 0 | AP4: PRO | AQ4: CONTRA | AS4: =GRUPOS!Q11 -> 0 | AT4: PRO | AU4: CONTRA
AG5: 1 | AH5: =TABELA_AVERAGE!AM8 -> 0 | AI5: =TABELA_AVERAGE!AO8 -> TOTAL | AK5: 1 | AL5: =TABELA_AVERAGE!AM12 -> 0 | AM5: =TABELA_AVERAGE!AO12 -> 0 | AO5: 1 | AP5: =TABELA_AVERAGE!AO12 -> 0 | AQ5: =TABELA_AVERAGE!AM12 -> 0 | AS5: 1 | AT5: =TABELA_AVERAGE!AO8 -> TOTAL | AU5: =TABELA_AVERAGE!AM8 -> 0
B6: FASE DE GRUPOS | P6: GRUPO A | R6: Partidas | X6: Ponto Average | AG6: 2 | AH6: =TABELA_AVERAGE!AM16 -> 0 | AI6: =TABELA_AVERAGE!AO16 -> 1 | AK6: 2 | AL6: =TABELA_AVERAGE!AM20 -> #DIV/0! | AM6: =TABELA_AVERAGE!AO20 -> MEDIA | AO6: 2 | AP6: =TABELA_AVERAGE!AO16 -> 1 | AQ6: =TABELA_AVERAGE!AM16 -> 0 | AS6: 2 | AT6: =TABELA_AVERAGE!AO20 -> MEDIA | AU6: =TABELA_AVERAGE!AM20 -> #DIV/0!
B7: Jogo | C7: Grupo | D7: Hora | E7: Quadra | F7: Código | G7: Equipe 1 | K7: Equipe 2 | L7: Código | R7: PF | S7: PC | T7: PF | U7: PC | V7: PF | W7: PC | X7: TPF | Y7: TPC | Z7: Score | AG7: 3 | AH7: =TABELA_AVERAGE!AM25 -> 0 | AI7: =TABELA_AVERAGE!AO24 -> 0 | AK7: 3 | AL7: =TABELA_AVERAGE!AO24 -> 0 | AM7: =TABELA_AVERAGE!AM25 -> 0 | AO7: 3 | AP7: =TABELA_AVERAGE!#REF! -> #REF! | AQ7: =TABELA_AVERAGE!#REF! -> #REF! | AS7: 3 | AT7: =TABELA_AVERAGE!#REF! -> #REF! | AU7: =TABELA_AVERAGE!#REF! -> #REF!
B8: 1 | C8: A | D8: 10:00 | F8: A1 | G8: =GRUPOS!C8 -> Ranking 1 | I8: X | K8: =GRUPOS!C11 -> Ranking 16 | L8: A4 | P8: A1 | Q8: =GRUPOS!C14 -> Ranking 1 | R8: =H8 -> 0 | S8: =J8 -> 0 | X8: =R8+T8+V8 -> 0 | Y8: =S8+U8+W8 -> 0 | Z8: =X8/Y8 -> #DIV/0! | AG8: TOTAL | AH8: =SUM(AH5:AH7) -> 0 | AI8: =SUM(AI5:AI7) -> 1 | AK8: TOTAL | AL8: =SUM(AL5:AL7) -> #DIV/0! | AM8: =SUM(AM5:AM7) -> 0 | AO8: TOTAL | AP8: =SUM(AP5:AP7) -> #REF! | AQ8: =SUM(AQ5:AQ7) -> #REF! | AS8: TOTAL | AT8: =SUM(AT5:AT7) -> #REF! | AU8: =SUM(AU5:AU7) -> #DIV/0!
B9: 2 | C9: B | D9: 10:00 | F9: B1 | G9: =GRUPOS!G8 -> Ranking 2 | I9: X | K9: =GRUPOS!G11 -> Ranking 15 | L9: B4 | P9: A2 | Q9: =GRUPOS!C21 -> Ranking 8 | R9: =H12 -> 0 | S9: =J12 -> 0 | X9: =R9+T9+V9 -> 0 | Y9: =S9+U9+W9 -> 0 | Z9: =X9/Y9 -> #DIV/0! | AG9: MEDIA | AI9: =AH8/AI8 -> 0 | AK9: MEDIA | AM9: =AL8/AM8 -> #DIV/0! | AO9: MEDIA | AQ9: =AP8/AQ8 -> #REF! | AS9: MEDIA | AU9: =AT8/AU8 -> #REF!
B10: 3 | C10: C | D10: 10:20 | F10: C1 | G10: =GRUPOS!K8 -> Ranking 3 | I10: X | K10: =GRUPOS!K11 -> Ranking 14 | L10: C4 | P10: A3 | Q10: =GRUPOS!K14 -> Ranking 9 | R10: =J12 -> 0 | S10: =H12 -> 0 | X10: =R10+T10+V10 -> 0 | Y10: =S10+U10+W10 -> 0 | Z10: =X10/Y10 -> #DIV/0!
B11: 4 | C11: D | D11: 10:20 | F11: D1 | G11: =GRUPOS!O8 -> Ranking 4 | I11: X | K11: =GRUPOS!O11 -> Ranking 13 | L11: D4 | P11: A4 | Q11: =GRUPOS!K21 -> Ranking 16 | R11: =J8 -> 0 | S11: =H8 -> 0 | X11: =R11+T11+V11 -> 0 | Y11: =S11+U11+W11 -> 0 | Z11: =X11/Y11 -> #DIV/0!
B12: 5 | C12: A | D12: 10:40 | F12: A2 | G12: =GRUPOS!C9 -> Ranking 8 | I12: X | K12: =GRUPOS!C10 -> Ranking 9 | L12: A3
B13: 6 | C13: B | D13: 10:40 | F13: B2 | G13: =GRUPOS!G9 -> Ranking 7 | I13: X | K13: =GRUPOS!G10 -> Ranking 10 | L13: B3 | P13: GRUPO B | R13: Partidas | X13: Ponto Average | AG13: GRUPO B
B14: 7 | C14: C | D14: 11:00 | F14: C2 | G14: =GRUPOS!K9 -> Ranking 6 | I14: X | K14: =GRUPOS!K10 -> Ranking 11 | L14: C3 | R14: PF | S14: PC | T14: PF | U14: PC | V14: PF | W14: PC | X14: TPF | Y14: TPC | Z14: Score
B15: 8 | C15: D | D15: 11:00 | F15: D2 | G15: =GRUPOS!O9 -> Ranking 5 | I15: X | K15: =GRUPOS!O10 -> Ranking 12 | L15: D3 | P15: B1 | Q15: =GRUPOS!C15 -> Ranking 2 | R15: =H9 -> 0 | S15: =J9 -> 0 | X15: =R15+T15+V15 -> 0 | Y15: =S15+U15+W15 -> 0 | Z15: =X15/Y15 -> #DIV/0! | AG15: =GRUPOS!U8 -> 0 | AH15: PRO | AI15: CONTRA | AK15: =GRUPOS!U9 -> 0 | AL15: PRO | AM15: CONTRA | AO15: =GRUPOS!U10 -> 0 | AP15: PRO | AQ15: CONTRA | AS15: =GRUPOS!U11 -> 0 | AT15: PRO | AU15: CONTRA
B16: 9 | C16: A | D16: 11:20 | F16: VJ1 | G16: Vencedor J1 | I16: X | K16: Vencedor J5 | L16: VJ5 | P16: B2 | Q16: =GRUPOS!C20 -> Ranking 7 | R16: =H13 -> 0 | S16: =J13 -> 0 | X16: =R16+T16+V16 -> 0 | Y16: =S16+U16+W16 -> 0 | Z16: =X16/Y16 -> #DIV/0! | AG16: 1 | AH16: =TABELA_AVERAGE!AM9 -> #DIV/0! | AI16: =TABELA_AVERAGE!AO9 -> MEDIA | AK16: 1 | AL16: =TABELA_AVERAGE!AM13 -> 0 | AM16: =TABELA_AVERAGE!AO13 -> 0 | AO16: 1 | AP16: =TABELA_AVERAGE!AO13 -> 0 | AQ16: =TABELA_AVERAGE!AM13 -> 0 | AS16: 1 | AT16: =TABELA_AVERAGE!AO9 -> MEDIA | AU16: =TABELA_AVERAGE!AM9 -> #DIV/0!
B17: 10 | C17: B | D17: 11:20 | F17: VJ2 | G17: Vencedor J2 | I17: X | K17: Vencedor J6 | L17: VJ6 | P17: B3 | Q17: =GRUPOS!K15 -> Ranking 10 | R17: =J13 -> 0 | S17: =H13 -> 0 | X17: =R17+T17+V17 -> 0 | Y17: =S17+U17+W17 -> 0 | Z17: =X17/Y17 -> #DIV/0! | AG17: 2 | AH17: =TABELA_AVERAGE!AM17 -> 0 | AI17: =TABELA_AVERAGE!AO17 -> 2 | AK17: 2 | AL17: =TABELA_AVERAGE!AM21 -> 0 | AM17: =TABELA_AVERAGE!AO21 -> 0 | AO17: 2 | AP17: =TABELA_AVERAGE!AO17 -> 2 | AQ17: =TABELA_AVERAGE!AM17 -> 0 | AS17: 2 | AT17: =TABELA_AVERAGE!AO21 -> 0 | AU17: =TABELA_AVERAGE!AM21 -> 0
B18: 11 | C18: C | D18: 11:40 | F18: VJ3 | G18: Vencedor J3 | I18: X | K18: Vencedor J7 | L18: VJ7 | P18: B4 | Q18: =GRUPOS!K20 -> Ranking 15 | R18: =J9 -> 0 | S18: =H9 -> 0 | X18: =R18+T18+V18 -> 0 | Y18: =S18+U18+W18 -> 0 | Z18: =X18/Y18 -> #DIV/0! | AG18: 3 | AH18: =TABELA_AVERAGE!AM25 -> 0 | AI18: =TABELA_AVERAGE!AO25 -> 0 | AK18: 3 | AL18: =TABELA_AVERAGE!AO25 -> 0 | AM18: =TABELA_AVERAGE!AM25 -> 0 | AO18: 3 | AP18: =TABELA_AVERAGE!#REF! -> #REF! | AQ18: =TABELA_AVERAGE!#REF! -> #REF! | AS18: 3 | AT18: =TABELA_AVERAGE!#REF! -> #REF! | AU18: =TABELA_AVERAGE!#REF! -> #REF!
B19: 12 | C19: D | D19: 11:40 | F19: VJ4 | G19: Vencedor J4 | I19: X | K19: Vencedor J8 | L19: VJ8 | AG19: TOTAL | AH19: =SUM(AH16:AH18) -> #DIV/0! | AI19: =SUM(AI16:AI18) -> 2 | AK19: TOTAL | AL19: =SUM(AL16:AL18) -> 0 | AM19: =SUM(AM16:AM18) -> 0 | AO19: TOTAL | AP19: =SUM(AP16:AP18) -> #REF! | AQ19: =SUM(AQ16:AQ18) -> #REF! | AS19: TOTAL | AT19: =SUM(AT16:AT18) -> #REF! | AU19: =SUM(AU16:AU18) -> #DIV/0!
B20: 13 | C20: A | D20: 12:00 | F20: PJ1 | G20: Perdedor J1 | I20: X | K20: Perdedor J5 | L20: PJ5 | P20: GRUPO C | R20: Partidas | X20: Ponto Average | AG20: MEDIA | AI20: =AH19/AI19 -> #DIV/0! | AK20: MEDIA | AM20: =AL19/AM19 -> #DIV/0! | AO20: MEDIA | AQ20: =AP19/AQ19 -> #REF! | AS20: MEDIA | AU20: =AT19/AU19 -> #REF!
B21: 14 | C21: B | D21: 12:00 | F21: PJ2 | G21: Perdedor J2 | I21: X | K21: Perdedor J6 | L21: PJ6 | R21: PF | S21: PC | T21: PF | U21: PC | V21: PF | W21: PC | X21: TPF | Y21: TPC | Z21: Score
B22: 15 | C22: C | D22: 12:20 | F22: PJ3 | G22: Perdedor J3 | I22: X | K22: Perdedor J7 | L22: PJ7 | P22: C1 | Q22: =GRUPOS!C16 -> Ranking 3 | R22: =H10 -> 0 | S22: =J10 -> 0 | X22: =R22+T22+V22 -> 0 | Y22: =S22+U22+W22 -> 0 | Z22: =X22/Y22 -> #DIV/0!
B23: 16 | C23: D | D23: 12:20 | F23: PJ4 | G23: Perdedor J4 | I23: X | K23: Perdedor J8 | L23: PJ8 | P23: C2 | Q23: =GRUPOS!C19 -> Ranking 6 | R23: =H14 -> 0 | S23: =J14 -> 0 | X23: =R23+T23+V23 -> 0 | Y23: =S23+U23+W23 -> 0 | Z23: =X23/Y23 -> #DIV/0!
B24: 17 | C24: A | D24: 12:40 | F24: PJ9 | G24: Perdedor J9 | I24: X | K24: Vencedor J13 | L24: VJ13 | P24: C3 | Q24: =GRUPOS!K16 -> Ranking 11 | R24: =J14 -> 0 | S24: =H14 -> 0 | X24: =R24+T24+V24 -> 0 | Y24: =S24+U24+W24 -> 0 | Z24: =X24/Y24 -> #DIV/0! | AG24: GRUPO C
B25: 18 | C25: B | D25: 12:40 | F25: PJ10 | G25: Perdedor J10 | I25: X | K25: Vencedor J14 | L25: VJ14 | P25: C4 | Q25: =GRUPOS!K19 -> Ranking 14 | R25: =J10 -> 0 | S25: =H10 -> 0 | X25: =R25+T25+V25 -> 0 | Y25: =S25+U25+W25 -> 0 | Z25: =X25/Y25 -> #DIV/0!
B26: 19 | C26: C | D26: 13:00 | F26: PJ11 | G26: Perdedor J11 | I26: X | K26: Vencedor J15 | L26: VJ15 | AG26: =GRUPOS!Y8 -> 0 | AH26: PRO | AI26: CONTRA | AK26: =GRUPOS!Y9 -> 0 | AL26: PRO | AM26: CONTRA | AO26: =GRUPOS!Y10 -> 0 | AP26: PRO | AQ26: CONTRA | AS26: =GRUPOS!Y11 -> 0 | AT26: PRO | AU26: CONTRA
B27: 20 | C27: D | D27: 13:00 | F27: PJ12 | G27: Perdedor J12 | I27: X | K27: Vencedor J16 | L27: VJ16 | P27: GRUPO D | R27: Partidas | X27: Ponto Average | AG27: 1 | AH27: =TABELA_AVERAGE!AM10 -> 0 | AI27: =TABELA_AVERAGE!AO10 -> 0 | AK27: 1 | AL27: =TABELA_AVERAGE!AM14 -> 0 | AM27: =TABELA_AVERAGE!AO14 -> 0 | AO27: 1 | AP27: =TABELA_AVERAGE!AO14 -> 0 | AQ27: =TABELA_AVERAGE!AM13 -> 0 | AS27: 1 | AT27: =TABELA_AVERAGE!AO10 -> 0 | AU27: =TABELA_AVERAGE!AM10 -> 0
R28: PF | S28: PC | T28: PF | U28: PC | V28: PF | W28: PC | X28: TPF | Y28: TPC | Z28: Score | AG28: 2 | AH28: =TABELA_AVERAGE!AM18 -> 0 | AI28: =TABELA_AVERAGE!AO18 -> 3 | AK28: 2 | AL28: =TABELA_AVERAGE!AM22 -> 0 | AM28: =TABELA_AVERAGE!AO22 -> 0 | AO28: 2 | AP28: =TABELA_AVERAGE!AO18 -> 3 | AQ28: =TABELA_AVERAGE!AM18 -> 0 | AS28: 2 | AT28: =TABELA_AVERAGE!AO22 -> 0 | AU28: =TABELA_AVERAGE!AM22 -> 0
B29: QUARTAS DE FINAL | P29: D1 | Q29: =GRUPOS!C17 -> Ranking 4 | R29: =H11 -> 0 | S29: =J11 -> 0 | X29: =R29+T29+V29 -> 0 | Y29: =S29+U29+W29 -> 0 | Z29: =X29/Y29 -> #DIV/0! | AG29: 3 | AH29: =TABELA_AVERAGE!AM26 -> CONTRA | AI29: =TABELA_AVERAGE!AO26 -> 0 | AK29: 3 | AL29: =TABELA_AVERAGE!AO26 -> 0 | AM29: =TABELA_AVERAGE!AM26 -> CONTRA | AO29: 3 | AP29: =TABELA_AVERAGE!#REF! -> #REF! | AQ29: =TABELA_AVERAGE!#REF! -> #REF! | AS29: 3 | AT29: =TABELA_AVERAGE!#REF! -> #REF! | AU29: =TABELA_AVERAGE!#REF! -> #REF!
B30: 21 | C30: QF | D30: 14:00 | F30: 1G | G30: =R36 -> 1º Geral | I30: X | K30: =R43 -> 8º Geral | L30: 8G | P30: D2 | Q30: =GRUPOS!C18 -> Ranking 5 | R30: =H15 -> 0 | S30: =J15 -> 0 | X30: =R30+T30+V30 -> 0 | Y30: =S30+U30+W30 -> 0 | Z30: =X30/Y30 -> #DIV/0! | AG30: TOTAL | AH30: =SUM(AH27:AH29) -> 0 | AI30: =SUM(AI27:AI29) -> 3 | AK30: TOTAL | AL30: =SUM(AL27:AL29) -> 0 | AM30: =SUM(AM27:AM29) -> 0 | AO30: TOTAL | AP30: =SUM(AP27:AP29) -> #REF! | AQ30: =SUM(AQ27:AQ29) -> #REF! | AS30: TOTAL | AT30: =SUM(AT27:AT29) -> #REF! | AU30: =SUM(AU27:AU29) -> #REF!
B31: 22 | C31: QF | D31: 14:00 | F31: 4G | G31: =R39 -> 4º Geral | I31: X | K31: =R40 -> 5º Geral | L31: 5G | P31: D3 | Q31: =GRUPOS!K17 -> Ranking 12 | R31: =J15 -> 0 | S31: =H15 -> 0 | X31: =R31+T31+V31 -> 0 | Y31: =S31+U31+W31 -> 0 | Z31: =X31/Y31 -> #DIV/0! | AG31: MEDIA | AI31: =AH30/AI30 -> 0 | AK31: MEDIA | AM31: =AL30/AM30 -> #DIV/0! | AO31: MEDIA | AQ31: =AP30/AQ30 -> #REF! | AS31: MEDIA | AU31: =AT30/AU30 -> #REF!
B32: 23 | C32: QF | D32: 14:20 | F32: 2G | G32: =R37 -> 2º Geral | I32: X | K32: =R42 -> 7º Geral | L32: 7G | P32: D4 | Q32: =GRUPOS!K18 -> Ranking 13 | R32: =J11 -> 0 | S32: =H11 -> 0 | X32: =R32+T32+V32 -> 0 | Y32: =S32+U32+W32 -> 0 | Z32: =X32/Y32 -> #DIV/0!
B33: 24 | C33: QF | D33: 14:20 | F33: 3G | G33: =R38 -> 3º Geral | I33: X | K33: =R41 -> 6º Geral | L33: 6G
P34: CLASSIFICAÇÃO GERAL
B35: SEMIFINAIS | P35: Ordem | Q35: Grupo | R35: Dupla | Z35: P. Average | AG35: GRUPO D
B36: 25 | C36: SF | D36: 14:40 | F36: VJ21 | G36: Venc. Jogo 21 | I36: X | K36: Venc. Jogo 22 | L36: VJ22 | P36: 1º | R36: 1º Geral
B37: 26 | C37: SF | D37: 14:00 | F37: VJ23 | G37: Venc. Jogo 23 | I37: X | K37: Venc. Jogo 24 | L37: VJ24 | P37: 2º | R37: 2º Geral | AG37: =GRUPOS!AC8 -> 0 | AH37: PRO | AI37: CONTRA | AK37: =GRUPOS!AC9 -> 0 | AL37: PRO | AM37: CONTRA | AO37: =GRUPOS!AC10 -> 0 | AP37: PRO | AQ37: CONTRA | AS37: =GRUPOS!AC11 -> 0 | AT37: PRO | AU37: CONTRA
P38: 3º | R38: 3º Geral | AG38: 1 | AH38: =TABELA_AVERAGE!AM11 -> 0 | AI38: =TABELA_AVERAGE!AO11 -> 0 | AK38: 1 | AL38: =TABELA_AVERAGE!AM15 -> CONTRA | AM38: =TABELA_AVERAGE!AO15 -> 0 | AO38: 1 | AP38: =TABELA_AVERAGE!AO15 -> 0 | AQ38: =TABELA_AVERAGE!AM15 -> CONTRA | AS38: 1 | AT38: =TABELA_AVERAGE!AO11 -> 0 | AU38: =TABELA_AVERAGE!AM11 -> 0
B39: DISPUTA 3º LUGAR | P39: 4º | R39: 4º Geral | AG39: 2 | AH39: =TABELA_AVERAGE!AM19 -> 0 | AI39: =TABELA_AVERAGE!AO19 -> TOTAL | AK39: 2 | AL39: =TABELA_AVERAGE!AM23 -> 0 | AM39: =TABELA_AVERAGE!AO23 -> 0 | AO39: 2 | AP39: =TABELA_AVERAGE!AO19 -> TOTAL | AQ39: =TABELA_AVERAGE!AM19 -> 0 | AS39: 2 | AT39: =TABELA_AVERAGE!AO23 -> 0 | AU39: =TABELA_AVERAGE!AM23 -> 0
B40: 27 | C40: F1 | D40: 15:00 | F40: PJ25 | G40: Perd. Jogo 25 | I40: X | K40: Perd. Jogo 36 | L40: PJ26 | P40: 5º | R40: 5º Geral | AG40: 3 | AH40: =TABELA_AVERAGE!AM27 -> 0 | AI40: =TABELA_AVERAGE!AO27 -> 1 | AK40: 3 | AL40: =TABELA_AVERAGE!AO27 -> 1 | AM40: =TABELA_AVERAGE!AM27 -> 0 | AO40: 3 | AP40: =TABELA_AVERAGE!#REF! -> #REF! | AQ40: =TABELA_AVERAGE!#REF! -> #REF! | AS40: 3 | AT40: =TABELA_AVERAGE!#REF! -> #REF! | AU40: =TABELA_AVERAGE!#REF! -> #REF!
P41: 6º | R41: 6º Geral | AG41: TOTAL | AH41: =SUM(AH38:AH40) -> 0 | AI41: =SUM(AI38:AI40) -> 1 | AK41: TOTAL | AL41: =SUM(AL38:AL40) -> 1 | AM41: =SUM(AM38:AM40) -> 0 | AO41: TOTAL | AP41: =SUM(AP38:AP40) -> #REF! | AQ41: =SUM(AQ38:AQ40) -> #REF! | AS41: TOTAL | AT41: =SUM(AT38:AT40) -> #REF! | AU41: =SUM(AU38:AU40) -> #REF!
...
