Workbook
Name FromArray_1: _xlfn.ANCHORARRAY(#REF!)

Sheet REGULAMENTO
B2: TORNEIO INTEGRAÇÃO ESPORTIVA
B3: Fitvôlei - Bloq - JR Integração - 2025
B5: REGULAMENTO
B7: VÔLEI DE PRAIA | D7: INICIANTE 1 | H7: 24/10/2025
H8: sexta-feira
B11: item | C11: Título | D11: Descrição | H11: Observação
B12: 1 | C12: Ranking de entrada | D12: Sorteio
B13: 2 | C13: Distribuição dos grupos | D13: Modelo de serpentina seguindo ranking definido por sorteio.
B14: 3 | C14: Quantidade de duplas | D14: 16 duplas (32 atletas).
B15: 4 | C15: Quantidade de jogos | D15: 32 partidas.
B16: 5 | C16: Quantidade de sets* | D16: 1 Set de 21 pontos.
B17: 6 | C17: Sistema de disputa da 1ª fase | D17: Todos contra todos no grupo. | H17: 3 jogos por equipe.
B18: 7 | C18: Classificação para as quartas-de-final | D18: Classificam-se os dois primeiros colocados de cada grupo.
B19: 8 | C19: Distribuição de confrontos nas quartas-de-final | D19: Classificação geral de 1º a 8º lugares, observando os seguintes critérios, INDEPENDENTE DA POSIÇÃO DE CLASSIFICAÇÃO NO GRUPO. | H19: 1º: nº de vitórias.
H20: 2º: ponto average.
H21: 3º: confronto direto.
H22: 3º: sorteio.
D23: Cruzamentos: (A: 1º X 8º) - (B: 4º X 5º) / (C: 2º X 7º) - (D: 3º X 6º)
B24: 9 | C24: Semifinais | D24: Cruzamentos: (A: 1º X 8º) versus (B: 4º X 5º) / (C: 2º X 7º) versus (D: 3º X 6º).
B25: 10 | C25: Final 1: disputa de 3º lugar | D25: 1 Set de 21 pontos.
B26: 11 | C26: Final 2: disputa de 1º lugar | D26: 1 Set de 21 pontos.
B27: 12 | C27: Pontuação em Wx0 | D27: As partidas resolvidas pela não apresentação de uma dupla resultará na vitória da dupla que se apresentou, contudo, não haverá saldo de pontos para nenhuma das duplas envolvidas. No caso de duplo W x 0, as duas duplas serão consideradas derrotadas e, consequentemente, sem saldo de pontos.
B28: 13 | C28: Pontuação em partida abandonada por desistência | D28: As partidas em que uma dupla desistir de continuar a partida, terá o placar de 21 (ou diferença de 2 pontos) para a equipe que não desistiu. A dupla que desistiu permanece com a pontuação do momento da desistência.
B29: 14 | C29: Penalidades | D29: A atleta que agir com desrespeito e violência em relação à arbitragem, adversários, parceiro e qualquer pessoa presente, poderá ser suspenso ou banido do Torneio por deliberação da Comissão Organizadora.
B30: 15 | C30: Suspensão de partidas | D30: As partidas que precisarem ser suspensas por motivos de mau tempo, falta de iluminação e assemelhados, retornará com o placar da interrupção, caso isso ocorra em até 4 horas. Após isso, a partida recomeçará com o placar de 0x0.
B31: 16 | C31: Uniformização | D31: Camiseta oficial do Torneio fornecida pela Comissão Organizadora | H31: Obrigatória.
D32: Bermudas da mesma cor. | H32: Preferencialmente.
B33: 17 | C33: Horário de início | D33: 18h em DUAS quadra.
B34: 18 | C34: Local da competição | D34: SMPW Qd 05 - Cj 09 - Lt 02 Park Way / Águas Claras

Sheet GRUPOS
B2: TORNEIO INTEGRAÇÃO ESPORTIVA
B3: Fitvôlei - Bloq - JR Integração - 2025
B5: INICIANTE 1
B6: 24 de outubro de 2025 - sexta-feira
B7: GRUPOS
B8: Distribuição pelo ranking no modo serpentina
B10: GRUPO A | F10: GRUPO B | J10: GRUPO C | N10: GRUPO D
B11: RK | C11: DUPLA | D11: CÓD | F11: RK | G11: DUPLA | H11: CÓD | J11: RK | K11: DUPLA | L11: CÓD | N11: RK | O11: DUPLA | P11: CÓD
B12: 1º | C12: =C18 -> ANA LUIZA/KAIO | D12: A1 | F12: 2º | G12: =C19 -> ANA C./VITOR BICHARA | H12: B1 | J12: 3º | K12: =C20 -> CRYS/LEO | L12: C1 | N12: 4º | O12: =C21 -> RAQUEL/ELIAS | P12: D1
B13: 8º | C13: =C25 -> JOSÉ/SARA | D13: A2 | F13: 7º | G13: =C24 -> THIAGO/DANILO | H13: B2 | J13: 6º | K13: =C23 -> BÁRBARA/JOÃO | L13: C2 | N13: 5º | O13: =C22 -> MARCOS/ANTÔNIO | P13: D2
B14: 9º | C14: =K18 -> MAYARA/DIVINO | D14: A3 | F14: 10º | G14: =K19 -> LARISSA/JÚLIA | H14: B3 | J14: 11º | K14: =K20 -> LUCAS/GABRIEL L. | L14: C3 | N14: 12º | O14: =K21 -> CLARINHA/ARTHUR | P14: D3
B15: 16º | C15: =K25 -> CYNTIA/SALVADOR | D15: A4 | F15: 15º | G15: =K24 -> ARTEMIS/BETO | H15: B4 | J15: 14º | K15: =K23 -> VINÍCIUS/PATRÍCIA | L15: C4 | N15: 13º | O15: =K22 -> PRISCILA/RAFA | P15: D4
B16: RANKING DEFINIDO POR SORTEIO
B17: RK | C17: Dupla | H17: CÓD | J17: RK | K17: Dupla | P17: CÓD
B18: 1º | C18: ANA LUIZA/KAIO | H18: A1 | J18: 9º | K18: MAYARA/DIVINO | P18: A3
B19: 2º | C19: ANA C./VITOR BICHARA | H19: B1 | J19: 10º | K19: LARISSA/JÚLIA | P19: B3
B20: 3º | C20: CRYS/LEO | H20: C1 | J20: 11º | K20: LUCAS/GABRIEL L. | P20: C3
B21: 4º | C21: RAQUEL/ELIAS | H21: D1 | J21: 12º | K21: CLARINHA/ARTHUR | P21: D3
B22: 5º | C22: MARCOS/ANTÔNIO | H22: D2 | J22: 13º | K22: PRISCILA/RAFA | P22: D4
B23: 6º | C23: BÁRBARA/JOÃO | H23: C2 | J23: 14º | K23: VINÍCIUS/PATRÍCIA | P23: C4
B24: 7º | C24: THIAGO/DANILO | H24: B2 | J24: 15º | K24: ARTEMIS/BETO | P24: B4
B25: 8º | C25: JOSÉ/SARA | H25: A2 | J25: 16º | K25: CYNTIA/SALVADOR | P25: A4
B28: ⚠️ | C28: DIGITAR NAS CÉLULAS LARANJA - Vai alimentar as abas TABELA e AVERAGE

Sheet TABELA FEM
B2: TORNEIO INTEGRAÇÃO ESPORTIVA
B3: Fitvôlei - Bloq - JR Integração - 2025
B5: INICIANTE 1
B6: 24 de outubro de 2025 - sexta-feira
B7: TABELA
B9: 1ª FASE
B10: Jogo | C10: Grupo | D10: Hora | E10: Quadra | F10: Código | G10: Equipe 1 | K10: Equipe 2 | L10: Código
B11: 1 | C11: A | D11: 18:00 | F11: A1 | G11: =GRUPOS!C12 -> ANA LUIZA/KAIO | H11: 21 | I11: X | J11: 19 | K11: =GRUPOS!C15 -> CYNTIA/SALVADOR | L11: A4
B12: 2 | C12: B | D12: 18:00 | F12: B1 | G12: =GRUPOS!G12 -> ANA C./VITOR BICHARA | H12: 21 | I12: X | J12: 18 | K12: =GRUPOS!G15 -> ARTEMIS/BETO | L12: B4
B13: 3 | C13: C | D13: 18:20 | F13: C1 | G13: =GRUPOS!K12 -> CRYS/LEO | H13: 12 | I13: X | J13: 21 | K13: =GRUPOS!K15 -> VINÍCIUS/PATRÍCIA | L13: C4
B14: 4 | C14: D | D14: 18:20 | F14: D1 | G14: =GRUPOS!O12 -> RAQUEL/ELIAS | H14: 14 | I14: X | J14: 21 | K14: =GRUPOS!O15 -> PRISCILA/RAFA | L14: D4
B15: 5 | C15: A | D15: 18:40 | F15: A2 | G15: =GRUPOS!C13 -> JOSÉ/SARA | H15: 15 | I15: X | J15: 21 | K15: =GRUPOS!C14 -> MAYARA/DIVINO | L15: A3
B16: 6 | C16: B | D16: 18:40 | F16: B2 | G16: =GRUPOS!G13 -> THIAGO/DANILO | H16: 21 | I16: X | J16: 18 | K16: =GRUPOS!G14 -> LARISSA/JÚLIA | L16: B3
B17: 7 | C17: C | D17: 19:00 | F17: C2 | G17: =GRUPOS!K13 -> BÁRBARA/JOÃO | H17: 25 | I17: X | J17: 23 | K17: =GRUPOS!K14 -> LUCAS/GABRIEL L. | L17: C3
B18: 8 | C18: D | D18: 19:00 | F18: D2 | G18: =GRUPOS!O13 -> MARCOS/ANTÔNIO | H18: 21 | I18: X | J18: 7 | K18: =GRUPOS!O14 -> CLARINHA/ARTHUR | L18: D3
B19: 9 | C19: A | D19: 19:20 | F19: A1 | G19: =GRUPOS!C12 -> ANA LUIZA/KAIO | H19: 21 | I19: X | J19: 9 | K19: =GRUPOS!C14 -> MAYARA/DIVINO | L19: A3
B20: 10 | C20: B | D20: 19:20 | F20: B1 | G20: =GRUPOS!G12 -> ANA C./VITOR BICHARA | H20: 10 | I20: X | J20: 21 | K20: =GRUPOS!G14 -> LARISSA/JÚLIA | L20: B3
B21: 11 | C21: C | D21: 19:40 | F21: C1 | G21: =GRUPOS!K12 -> CRYS/LEO | H21: 11 | I21: X | J21: 21 | K21: =GRUPOS!K14 -> LUCAS/GABRIEL L. | L21: C3
B22: 12 | C22: D | D22: 19:40 | F22: D1 | G22: =GRUPOS!O12 -> RAQUEL/ELIAS | H22: 21 | I22: X | J22: 18 | K22: =GRUPOS!O14 -> CLARINHA/ARTHUR | L22: D3
B23: 13 | C23: A | D23: 20:00 | F23: A2 | G23: =GRUPOS!C13 -> JOSÉ/SARA | H23: 17 | I23: X | J23: 21 | K23: =GRUPOS!C15 -> CYNTIA/SALVADOR | L23: A4
B24: 14 | C24: B | D24: 20:00 | F24: B2 | G24: =GRUPOS!G13 -> THIAGO/DANILO | H24: 14 | I24: X | J24: 21 | K24: =GRUPOS!G15 -> ARTEMIS/BETO | L24: B4
B25: 15 | C25: C | D25: 20:20 | F25: C2 | G25: =GRUPOS!K13 -> BÁRBARA/JOÃO | H25: 21 | I25: X | J25: 12 | K25: =GRUPOS!K15 -> VINÍCIUS/PATRÍCIA | L25: C4
B26: 16 | C26: D | D26: 20:20 | F26: D2 | G26: =GRUPOS!O13 -> MARCOS/ANTÔNIO | H26: 21 | I26: X | J26: 11 | K26: =GRUPOS!O15 -> PRISCILA/RAFA | L26: D4
B27: 17 | C27: A | D27: 20:40 | F27: A1 | G27: =GRUPOS!C12 -> ANA LUIZA/KAIO | H27: 21 | I27: X | J27: 11 | K27: =GRUPOS!C13 -> JOSÉ/SARA | L27: A2
B28: 18 | C28: B | D28: 20:40 | F28: B1 | G28: =GRUPOS!G12 -> ANA C./VITOR BICHARA | H28: 21 | I28: X | J28: 18 | K28: =GRUPOS!G13 -> THIAGO/DANILO | L28: B2
B29: 19 | C29: C | D29: 21:00 | F29: C1 | G29: =GRUPOS!K12 -> CRYS/LEO | H29: 17 | I29: X | J29: 21 | K29: =GRUPOS!K13 -> BÁRBARA/JOÃO | L29: C2
B30: 20 | C30: D | D30: 21:00 | F30: D1 | G30: =GRUPOS!O12 -> RAQUEL/ELIAS | H30: 14 | I30: X | J30: 21 | K30: =GRUPOS!O13 -> MARCOS/ANTÔNIO | L30: D2
B31: 21 | C31: A | D31: 21:20 | F31: A3 | G31: =GRUPOS!C14 -> MAYARA/DIVINO | H31: 21 | I31: X | J31: 18 | K31: =GRUPOS!C15 -> CYNTIA/SALVADOR | L31: A4
B32: 22 | C32: B | D32: 21:20 | F32: B3 | G32: =GRUPOS!G14 -> LARISSA/JÚLIA | H32: 17 | I32: X | J32: 21 | K32: =GRUPOS!G15 -> ARTEMIS/BETO | L32: B4
B33: 23 | C33: C | D33: 21:40 | F33: C3 | G33: =GRUPOS!K14 -> LUCAS/GABRIEL L. | H33: 14 | I33: X | J33: 21 | K33: =GRUPOS!K15 -> VINÍCIUS/PATRÍCIA | L33: C4
B34: 24 | C34: D | D34: 21:40 | F34: D3 | G34: =GRUPOS!O14 -> CLARINHA/ARTHUR | H34: 21 | I34: X | J34: 11 | K34: =GRUPOS!O15 -> PRISCILA/RAFA | L34: D4
B36: QUARTAS DE FINAL
B37: 25 | C37: QF | D37: 22:00 | F37: 1º | G37: ='AVERAGE FEM'!C57 -> 1º Colocado Geral | I37: X | K37: ='AVERAGE FEM'!C64 -> 8º Colocado Geral | L37: 8º | O37: ⚠️ | P37: <= Não digitar aqui.
B38: 26 | C38: QF | D38: 22:00 | F38: 4º | G38: ='AVERAGE FEM'!C60 -> 4º Colocado Geral | I38: X | K38: ='AVERAGE FEM'!C61 -> 5º Colocado Geral | L38: 5º
B39: 27 | C39: QF | D39: 22:20 | F39: 2º | G39: ='AVERAGE FEM'!C58 -> 2º Colocado Geral | I39: X | K39: ='AVERAGE FEM'!C63 -> 7º Colocado Geral | L39: 7º | P39: Digitar na aba Average.
B40: 28 | C40: QF | D40: 22:20 | F40: 3º | G40: ='AVERAGE FEM'!C59 -> 3º Colocado Geral | I40: X | K40: ='AVERAGE FEM'!C62 -> 6º Colocado Geral | L40: 6º
B42: SEMIFINAIS
B43: 29 | C43: SF | D43: 22:40 | F43: V J 25 | G43: Vencedor Jogo 25 | I43: X | K43: Vencedor Jogo 26 | L43: V J 26 | O43: ⚠️ | P43: Digitar nas células Laranja
B44: 30 | C44: SF | D44: 22:40 | F44: V J 27 | G44: Vencedor Jogo 27 | I44: X | K44: Vencedor Jogo 28 | L44: V J 28
B46: DISPUTA 3º LUGAR
...

Sheet AVERAGE FEM
B2: TORNEIO INTEGRAÇÃO ESPORTIVA
B3: Fitvôlei - Bloq - JR Integração - 2025
B5: INICIANTE 1
B6: 24 de outubro de 2025 - sexta-feira
B7: AVERAGE
B11: GRUPO A
B13: =GRUPOS!C12 -> ANA LUIZA/KAIO | C13: PRO | D13: CONTRA | F13: =GRUPOS!C13 -> JOSÉ/SARA | G13: PRO | H13: CONTRA | J13: =GRUPOS!C14 -> MAYARA/DIVINO | K13: PRO | L13: CONTRA | N13: =GRUPOS!C15 -> CYNTIA/SALVADOR | O13: PRO | P13: CONTRA
B14: 1 | C14: ='TABELA FEM'!H11 -> 21 | D14: ='TABELA FEM'!J11 -> 19 | F14: 1 | G14: ='TABELA FEM'!H15 -> 15 | H14: ='TABELA FEM'!J15 -> 21 | J14: 1 | K14: ='TABELA FEM'!J15 -> 21 | L14: ='TABELA FEM'!H15 -> 15 | N14: 1 | O14: ='TABELA FEM'!J11 -> 19 | P14: ='TABELA FEM'!H11 -> 21
B15: 2 | C15: ='TABELA FEM'!H19 -> 21 | D15: ='TABELA FEM'!J19 -> 9 | F15: 2 | G15: ='TABELA FEM'!H23 -> 17 | H15: ='TABELA FEM'!J23 -> 21 | J15: 2 | K15: ='TABELA FEM'!J19 -> 9 | L15: ='TABELA FEM'!H19 -> 21 | N15: 2 | O15: ='TABELA FEM'!J23 -> 21 | P15: ='TABELA FEM'!H23 -> 17
B16: 3 | C16: ='TABELA FEM'!H28 -> 21 | D16: ='TABELA FEM'!J27 -> 11 | F16: 3 | G16: ='TABELA FEM'!J27 -> 11 | H16: ='TABELA FEM'!H28 -> 21 | J16: 3 | K16: ='TABELA FEM'!H31 -> 21 | L16: ='TABELA FEM'!J31 -> 18 | N16: 3 | O16: ='TABELA FEM'!J31 -> 18 | P16: ='TABELA FEM'!H31 -> 21
B17: TOTAL | C17: =SUM(C14:C16) -> 63 | D17: =SUM(D14:D16) -> 39 | F17: TOTAL | G17: =SUM(G14:G16) -> 43 | H17: =SUM(H14:H16) -> 63 | J17: TOTAL | K17: =SUM(K14:K16) -> 51 | L17: =SUM(L14:L16) -> 54 | N17: TOTAL | O17: =SUM(O14:O16) -> 58 | P17: =SUM(P14:P16) -> 59
B18: MEDIA | D18: =C17/D17 -> 1.6153846 | F18: MEDIA | H18: =G17/H17 -> 0.68253968 | J18: MEDIA | L18: =K17/L17 -> 0.94444444 | N18: MEDIA | P18: =O17/P17 -> 0.98305085
B22: GRUPO B
B24: =GRUPOS!G12 -> ANA C./VITOR BICHARA | C24: PRO | D24: CONTRA | F24: =GRUPOS!G13 -> THIAGO/DANILO | G24: PRO | H24: CONTRA | J24: =GRUPOS!G14 -> LARISSA/JÚLIA | K24: PRO | L24: CONTRA | N24: =GRUPOS!G15 -> ARTEMIS/BETO | O24: PRO | P24: CONTRA
B25: 1 | C25: ='TABELA FEM'!H12 -> 21 | D25: ='TABELA FEM'!J12 -> 18 | F25: 1 | G25: ='TABELA FEM'!H16 -> 21 | H25: ='TABELA FEM'!J16 -> 18 | J25: 1 | K25: ='TABELA FEM'!J16 -> 18 | L25: ='TABELA FEM'!H16 -> 21 | N25: 1 | O25: ='TABELA FEM'!J12 -> 18 | P25: ='TABELA FEM'!H12 -> 21
B26: 2 | C26: ='TABELA FEM'!H20 -> 10 | D26: ='TABELA FEM'!J20 -> 21 | F26: 2 | G26: ='TABELA FEM'!H24 -> 14 | H26: ='TABELA FEM'!J24 -> 21 | J26: 2 | K26: ='TABELA FEM'!J20 -> 21 | L26: ='TABELA FEM'!H20 -> 10 | N26: 2 | O26: ='TABELA FEM'!J24 -> 21 | P26: ='TABELA FEM'!H24 -> 14
B27: 3 | C27: ='TABELA FEM'!H28 -> 21 | D27: ='TABELA FEM'!J28 -> 18 | F27: 3 | G27: ='TABELA FEM'!J28 -> 18 | H27: ='TABELA FEM'!H28 -> 21 | J27: 3 | K27: ='TABELA FEM'!H32 -> 17 | L27: ='TABELA FEM'!J32 -> 21 | N27: 3 | O27: ='TABELA FEM'!J32 -> 21 | P27: ='TABELA FEM'!H32 -> 17
B28: TOTAL | C28: =SUM(C25:C27) -> 52 | D28: =SUM(D25:D27) -> 57 | F28: TOTAL | G28: =SUM(G25:G27) -> 53 | H28: =SUM(H25:H27) -> 60 | J28: TOTAL | K28: =SUM(K25:K27) -> 56 | L28: =SUM(L25:L27) -> 52 | N28: TOTAL | O28: =SUM(O25:O27) -> 60 | P28: =SUM(P25:P27) -> 52
B29: MEDIA | D29: =C28/D28 -> 0.9122807 | F29: MEDIA | H29: =G28/H28 -> 0.88333333 | J29: MEDIA | L29: =K28/L28 -> 1.0769231 | N29: MEDIA | P29: =O28/P28 -> 1.1538462
B33: GRUPO C
B35: =GRUPOS!K12 -> CRYS/LEO | C35: PRO | D35: CONTRA | F35: =GRUPOS!K13 -> BÁRBARA/JOÃO | G35: PRO | H35: CONTRA | J35: =GRUPOS!K14 -> LUCAS/GABRIEL L. | K35: PRO | L35: CONTRA | N35: =GRUPOS!K15 -> VINÍCIUS/PATRÍCIA | O35: PRO | P35: CONTRA
B36: 1 | C36: ='TABELA FEM'!H13 -> 12 | D36: ='TABELA FEM'!J13 -> 21 | F36: 1 | G36: ='TABELA FEM'!H17 -> 25 | H36: ='TABELA FEM'!J17 -> 23 | J36: 1 | K36: ='TABELA FEM'!J17 -> 23 | L36: ='TABELA FEM'!H16 -> 21 | N36: 1 | O36: ='TABELA FEM'!J13 -> 21 | P36: ='TABELA FEM'!H13 -> 12
B37: 2 | C37: ='TABELA FEM'!H21 -> 11 | D37: ='TABELA FEM'!J21 -> 21 | F37: 2 | G37: ='TABELA FEM'!H25 -> 21 | H37: ='TABELA FEM'!J25 -> 12 | J37: 2 | K37: ='TABELA FEM'!J21 -> 21 | L37: ='TABELA FEM'!H21 -> 11 | N37: 2 | O37: ='TABELA FEM'!J25 -> 12 | P37: ='TABELA FEM'!H25 -> 21
B38: 3 | C38: ='TABELA FEM'!H29 -> 17 | D38: ='TABELA FEM'!J29 -> 21 | F38: 3 | G38: ='TABELA FEM'!J29 -> 21 | H38: ='TABELA FEM'!H29 -> 17 | J38: 3 | K38: ='TABELA FEM'!H33 -> 14 | L38: ='TABELA FEM'!J33 -> 21 | N38: 3 | O38: ='TABELA FEM'!J33 -> 21 | P38: ='TABELA FEM'!H33 -> 14
B39: TOTAL | C39: =SUM(C36:C38) -> 40 | D39: =SUM(D36:D38) -> 63 | F39: TOTAL | G39: =SUM(G36:G38) -> 67 | H39: =SUM(H36:H38) -> 52 | J39: TOTAL | K39: =SUM(K36:K38) -> 58 | L39: =SUM(L36:L38) -> 53 | N39: TOTAL | O39: =SUM(O36:O38) -> 54 | P39: =SUM(P36:P38) -> 47
B40: MEDIA | D40: =C39/D39 -> 0.63492063 | F40: MEDIA | H40: =G39/H39 -> 1.2884615 | J40: MEDIA | L40: =K39/L39 -> 1.0943396 | N40: MEDIA | P40: =O39/P39 -> 1.1489362
B44: GRUPO D
B46: =GRUPOS!O12 -> RAQUEL/ELIAS | C46: PRO | D46: CONTRA | F46: =GRUPOS!O13 -> MARCOS/ANTÔNIO | G46: PRO | H46: CONTRA | J46: =GRUPOS!O14 -> CLARINHA/ARTHUR | K46: PRO | L46: CONTRA | N46: =GRUPOS!O15 -> PRISCILA/RAFA | O46: PRO | P46: CONTRA
B47: 1 | C47: ='TABELA FEM'!H14 -> 14 | D47: ='TABELA FEM'!J14 -> 21 | F47: 1 | G47: ='TABELA FEM'!H18 -> 21 | H47: ='TABELA FEM'!J18 -> 7 | J47: 1 | K47: ='TABELA FEM'!J18 -> 7 | L47: ='TABELA FEM'!H18 -> 21 | N47: 1 | O47: ='TABELA FEM'!J14 -> 21 | P47: ='TABELA FEM'!H14 -> 14
B48: 2 | C48: ='TABELA FEM'!H22 -> 21 | D48: ='TABELA FEM'!J22 -> 18 | F48: 2 | G48: ='TABELA FEM'!H26 -> 21 | H48: ='TABELA FEM'!J26 -> 11 | J48: 2 | K48: ='TABELA FEM'!J22 -> 18 | L48: ='TABELA FEM'!H22 -> 21 | N48: 2 | O48: ='TABELA FEM'!J26 -> 11 | P48: ='TABELA FEM'!H26 -> 21
B49: 3 | C49: ='TABELA FEM'!H30 -> 14 | D49: ='TABELA FEM'!J30 -> 21 | F49: 3 | G49: ='TABELA FEM'!J30 -> 21 | H49: ='TABELA FEM'!H30 -> 14 | J49: 3 | K49: ='TABELA FEM'!H34 -> 21 | L49: ='TABELA FEM'!J34 -> 11 | N49: 3 | O49: ='TABELA FEM'!J34 -> 11 | P49: ='TABELA FEM'!H34 -> 21
B50: TOTAL | C50: =SUM(C47:C49) -> 49 | D50: =SUM(D47:D49) -> 60 | F50: TOTAL | G50: =SUM(G47:G49) -> 63 | H50: =SUM(H47:H49) -> 32 | J50: TOTAL | K50: =SUM(K47:K49) -> 46 | L50: =SUM(L47:L49) -> 53 | N50: TOTAL | O50: =SUM(O47:O49) -> 43 | P50: =SUM(P47:P49) -> 56
B51: MEDIA | D51: =C50/D50 -> 0.81666667 | F51: MEDIA | H51: =G50/H50 -> 1.96875 | J51: MEDIA | L51: =K50/L50 -> 0.86792453 | N51: MEDIA | P51: =O50/P50 -> 0.76785714
B55: CLASSIFICADOS
B56: POSIÇÃO | C56: DUPLA | K56: VITÓRIAS | M56: CLASSIFICAÇÃO NO GRUPO | O56: AVERAGE
B57: 1º | C57: 1º Colocado Geral
B58: 2º | C58: 2º Colocado Geral
B59: 3º | C59: 3º Colocado Geral
B60: 4º | C60: 4º Colocado Geral
B61: 5º | C61: 5º Colocado Geral
...
